Workbook

Sheet Form responses 1
A1: # | B1: Timestamp | C1: Email address | D1: Surveyor Name | E1: Road Name (Main) | F1: Road Name (Cross) | G1: Area Name | H1: Dist. (m) | I1: Location (Google Maps link) | J1: Road Sign | K1: Use | L1: Material | M1: Width (m) | N1: Road Condition | O1: Side (N/E) | P1: Attachment 1 Type | Q1: Attachment 1 Width (m) | R1: Attachment 1 Dated | S1: Attachment 1 Condition | T1: Attachment 1 Notes | U1: Attachment 2 Type | V1: Attachment 2 Width (m) | W1: Attachment 2 Dated | X1: Attachment 2 Condition | Y1: Attachment 2 Notes | Z1: Side (S/W) | AA1: Attachment 1 Type (S/W) | AB1: Attachment 1 Width (m) (S/W) | AC1: Attachment 1 Dated (S/W) | AD1: Attachment 1 Condition (S/W) | AE1: Attachment 1 Notes (S/W) | AF1: Attachment 2 Type (S/W) | AG1: Attachment 2 Width (m) (S/W) | AH1: Attachment 2 Dated (S/W) | AI1: Attachment 2 Condition (S/W) | AJ1: Attachment 2 Notes (S/W) | AK1: SWG Side (N/E) | AL1: SWG Type (N/E) | AM1: SWG Width (m) (N/E) | AN1: SWG Dated (N/E) | AO1: SWG Condition (N/E) | AP1: SWG Notes (N/E) | AQ1: SWG Side (S/W) | AR1: SWG Width (m) (S/W) | AS1: SWG Dated (S/W) | AT1: SWG Condition (S/W) | AU1: SWG Notes (S/W) | AV1: UGD Existing | AW1: UGD Type | AX1: UGD Date | AY1: UGD Pipe Dia (m) | AZ1: UGD Condition | BA1: Jalasiri Existing | BB1: Jalasiri Condition | BC1: Jalasiri Note | BD1: Light Type | BE1: Electrical Condition
A2: 1 | B2: 46224.483 | C2: meghansnaik739@gmail.com | D2: Meghan S Naik | E2: Maharajpet road | I2: ?? | J2: Yes | K2: Residential | L2: Concrete | M2: 4.3 | N2: Good | O2: East | Q2: 1.5 | R2: 42572 | S2: n/a | T2: Footpath development required | Z2: West | AA2: Pavers | AB2: 1.2 | AC2: 42572 | AD2: Required | AE2: Footpath development required | AK2: East | AL2: FFL Gutter | AM2: 0.6 | AN2: 44763 | AO2: Good | AQ2: West | AR2: 0.45 | AS2: 42572 | AT2: Good | AU2: Some portion cover slab required | AV2: Yes | AW2: Stone | AX2: 42206 | AY2: 0.225 | AZ2: Outdated | BA2: Yes | BB2: Good | BD2: LED- Pole | BE2: Good
A3: 2 | B3: 46224.497 | C3: meghansnaik739@gmail.com | D3: Meghan | E3: Conservency | F3: Mallikarjun temple back road | H3: 98 | I3: ?? | J3: Yes | K3: Conservency | L3: Concrete | M3: 2.3 | N3: Good | O3: East | S3: Required | T3: Not existing | Z3: West | AB3: 0.45 | AC3: 44398 | AD3: Good | AE3: Good | AK3: North | AL3: FFL Gutter | AM3: 0.46 | AN3: 44398 | AO3: Good | AP3: Some cleaning work required | AU3: No | AV3: Yes | AW3: Stone | AX3: 44763 | AY3: 0.225 | AZ3: Good | BA3: Yes | BB3: Good | BD3: LED- LT Line | BE3: Good
A4: 3 | B4: 46224.503 | C4: meghansnaik739@gmail.com | D4: Meghan | E4: Bommalingya galli | F4: 11 | G4: Ward 11 | H4: 100.23 | I4: ?? | J4: Yes | K4: Residential | L4: Concrete | M4: 3.8 | N4: Good | O4: East | Q4: 1 | R4: 42572 | S4: Required | T4: No existing attachments | Z4: West | AC4: 42572 | AD4: Required | AK4: East | AL4: FFL Gutter | AM4: 1.1 | AN4: 42572 | AQ4: West | AS4: 42572 | AT4: Good | AV4: Yes | AW4: Stone | AX4: 42206 | AY4: 0.225 | AZ4: Good | BA4: Yes | BB4: Good | BD4: LED- LT Line | BE4: Good
A5: 4 | B5: 46224.508 | C5: meghansnaik739@gmail.com | D5: Meghan | E5: Kadlebalu nanjappa galli | G5: Ward 11 | H5: 108.6 | I5: ?? | J5: No | K5: Residential | L5: Concrete | M5: 4.3 | N5: Good | O5: n/a | P5: n/a | Q5: 0 | R5: n/a | S5: n/a | T5: -- | AK5: East | AL5: FFL Gutter | AM5: 0.5 | AN5: 42572 | AO5: Good | AQ5: West | AR5: 0.5 | AS5: 42572 | AT5: Good | AU5: Good | AV5: Yes | AW5: Stone | AX5: 42572 | AY5: 0.225 | AZ5: Good | BA5: Yes | BB5: Good
A6: 5 | B6: 46224.514 | C6: meghansnaik739@gmail.com | D6: Meghan | E6: Sub | F6: Karishivappana galli | G6: Ward 11 | H6: 124.7 | I6: ?? | J6: Yes | K6: Residential | L6: Concrete | M6: 2.9 | N6: Good | O6: East | P6: Pavers | Q6: 1 | R6: 44033 | S6: Required | T6: No work been done | Z6: West | AK6: East | AL6: FFL Gutter | AM6: 0.5 | AN6: 42572 | AO6: Maintenance | AP6: Debris removal work to be needed | AQ6: West | AR6: 0.5 | AS6: 42572 | AT6: Good | AU6: Good | AV6: Yes | AW6: Stone | AX6: 42572 | AY6: 0.225 | AZ6: Good | BA6: Yes | BB6: Good | BD6: LED- LT Line | BE6: Good
A7: 6 | B7: 46224.52 | C7: meghansnaik739@gmail.com | D7: Megh | E7: Ejardhar galli | G7: Ward 11 | H7: 152.8 | I7: ?? | J7: Yes | K7: Residential | L7: Concrete | M7: 4.4 | N7: Good | O7: East | Z7: West | AA7: Pavers | AK7: East | AL7: FFL Gutter | AP7: No drainage existing | AQ7: West | AR7: 0.45 | AS7: 44398 | AT7: Good | AV7: Yes | AW7: PVC | AX7: 45859 | AY7: 0.225 | AZ7: Good | BA7: Yes | BB7: Good | BD7: LED- LT Line | BE7: Good
A8: 7 | B8: 46224.526 | C8: meghansnaik739@gmail.com | D8: Megh | E8: Sub | F8: Chigateri galli | G8: Ward 11 | H8: 172.5 | I8: ?? | J8: Yes | K8: Residential | L8: Concrete | M8: 3 | N8: Good | O8: East | P8: Pavers | Z8: West | AA8: Pavers | AK8: East | AL8: FFL Gutter | AM8: 0.45 | AN8: 44398 | AO8: Good | AP8: Good | AQ8: West | AR8: 0.45 | AS8: 44398 | AT8: Good | AV8: Yes | AW8: Stone | AX8: 42572 | AY8: 0.225 | AZ8: Good | BA8: Yes | BB8: Good | BD8: LED- LT Line | BE8: Good
A9: 8 | B9: 46224.531 | C9: meghansnaik739@gmail.com | D9: Megh | E9: Sub | F9: Hubballi chowdappana galli | G9: Ward 11 | H9: 532.49 | I9: ?? | J9: Yes | K9: Residential | L9: Concrete | M9: 5 | N9: Good | O9: East | P9: Pavers | AK9: East | AL9: FFL Gutter | AM9: 0.45 | AN9: 42572 | AO9: Good | AQ9: West | AR9: 0.5 | AS9: 42572 | AT9: Good | AV9: Yes | AW9: Stone | AX9: 42572 | AY9: 0.225 | AZ9: Good | BA9: Yes | BB9: Good | BD9: LED- LT Line | BE9: Good
A10: 9 | B10: 46224.536 | C10: meghansnaik739@gmail.com | D10: Meghan | E10: Sub | F10: Basawaraj pete 2nd c/s | G10: Ward 11 | H10: 543.01 | I10: ?? | J10: No | K10: Residential | L10: Concrete | M10: 3 | N10: Good | O10: East | P10: Pavers | Q10: 1 | R10: 45494 | S10: Good | Z10: West | AA10: Pavers | AB10: 1 | AC10: 45494 | AD10: Good | AE10: Good and perfect | AK10: East | AL10: FFL Gutter | AM10: 0.5 | AN10: 42572 | AO10: Good | AQ10: West | AR10: 0.5 | AS10: 42572 | AT10: Good | AV10: Yes | AW10: Stone | AX10: 42572 | AY10: 0.225 | AZ10: Good | BA10: Yes | BB10: Good | BD10: LED- LT Line | BE10: Good
A11: 10 | B11: 46224.54 | C11: meghansnaik739@gmail.com | D11: Megh | E11: Maharaj road | F11: Basawaraj pete 1st c/s | G11: Ward 11 | H11: 561.1 | I11: ?? | J11: No | K11: Residential | L11: Concrete | M11: 4.4 | N11: Good | O11: East | P11: Pavers | Q11: 1 | R11: 45494 | S11: Good | Z11: West | AA11: Pavers | AB11: 1 | AC11: 45494 | AD11: Good | AK11: East | AL11: FFL Gutter | AM11: 0.5 | AN11: 42572 | AO11: Good | AQ11: West | AR11: 0.5 | AS11: 42572 | AT11: Good | AV11: Yes | AW11: Stone | AX11: 42567 | AY11: 0.225 | AZ11: Good | BA11: Yes | BB11: Good | BD11: LED- LT Line | BE11: Good
A12: 11 | B12: 46224.545 | C12: meghansnaik739@gmail.com | D12: Megh | E12: Old bethur road | F12: Main road | G12: Ward 11 | H12: 665.2 | I12: ?? | J12: Yes | K12: Main Rd | L12: Concrete | M12: 6.3 | N12: Good | O12: East | P12: Pavers | Z12: West | AA12: Pavers | AP12: Not in ward 11 | AQ12: West | AR12: 0.5 | AS12: 42572 | AT12: Good | AV12: Yes | AW12: Stone | AX12: 42572 | AY12: 0.225 | AZ12: Good | BA12: Yes | BB12: Maintenance | BD12: LED- LT Line | BE12: Good
A13: 12 | B13: 46224.558 | C13: meghansnaik739@gmail.com | D13: Meghan | E13: Maharaj pete road | F13: Concorence | G13: Ward 11 | H13: 60.61 | I13: ?? | J13: No | K13: Conservency | L13: Concrete | M13: 2.6 | N13: Good | O13: n/a | P13: n/a | Q13: 0 | R13: n/a | S13: n/a | T13: -- | AP13: No | AQ13: West | AR13: 0.3 | AS13: 46224 | AT13: Maintenance | AU13: Pipe drain | AV13: Yes | AW13: Stone | AX13: 42572 | AY13: 0.225 | AZ13: Good | BA13: Yes | BB13: Good | BD13: LED- LT Line | BE13: Good
A14: 13 | B14: 46224.563 | C14: meghansnaik739@gmail.com | D14: Meghan | E14: Maharaj pete road | F14: Hijadhar galli 1 st crosss | G14: Ward 11 | H14: 86.25 | I14: ?? | J14: No | K14: Conservency | L14: ?? | M14: 2.8 | N14: Good | O14: n/a | P14: n/a | Q14: 0 | R14: n/a | S14: n/a | T14: -- | AK14: East | AL14: FFL Gutter | AM14: 0.5 | AN14: 42572 | AO14: Maintenance | AQ14: West | AR14: 0.5 | AS14: 42572 | AT14: Maintenance | AV14: Yes | AW14: Stone | AX14: 42572 | AY14: 0.225 | AZ14: Good | BA14: Yes | BB14: Good | BD14: LED- LT Line | BE14: Good
A15: 14 | B15: 46224.568 | C15: meghansnaik739@gmail.com | D15: Meghan S | E15: Hijadhar galli | F15: 2nd cs | G15: Ward 11 | H15: 15 | I15: ?? | J15: Yes | K15: Conservency | L15: ?? | M15: 2.8 | N15: Good | O15: n/a | P15: n/a | Q15: 0 | R15: n/a | S15: n/a | T15: -- | AO15: N/A | AP15: No swg existing | AU15: No swg existing | AV15: Yes | AW15: Stone | AX15: 42257 | AY15: 0.225 | AZ15: Maintenance | BA15: Yes | BB15: Good | BD15: LED- LT Line | BE15: Outdated
A16: 15 | B16: 46224.571 | C16: meghansnaik739@gmail.com | D16: Meghan S | E16: Hijadar galli | F16: 3rd cs | G16: Ward 11 | H16: 28 | I16: ?? | J16: Yes | K16: Conservency | L16: Concrete | M16: 3.2 | N16: Maintenance | O16: n/a | P16: n/a | Q16: 0 | R16: n/a | S16: n/a | T16: -- | AK16: East | AL16: FFL Gutter | AN16: 42572 | AO16: Maintenance | AQ16: West | AU16: No | AV16: Yes | AW16: Stone | AX16: 42572 | AY16: 0.225 | AZ16: Maintenance | BA16: Yes | BB16: Good
A17: 16 | B17: 46224.577 | C17: meghansnaik739@gmail.com | D17: Meghan S | E17: Bsc | F17: Infront of kalikadevi temple (concorence) | G17: Ward 11 | H17: 20 | I17: ?? | J17: No | K17: Conservency | L17: Concrete | M17: 3 | N17: Good | O17: n/a | P17: n/a | Q17: 0 | R17: n/a | S17: n/a | T17: -- | AA17: Pavers | AE17: Required | AK17: East | AL17: FFL Gutter | AM17: 0.5 | AN17: 42572 | AO17: Good | AQ17: West | AR17: 0.5 | AS17: 42572 | AT17: Good | AV17: Yes | AW17: Stone | AX17: 42572 | AY17: 0.225 | AZ17: Good | BA17: Yes | BB17: Good | BD17: LED- LT Line | BE17: Good
A18: 17 | B18: 46225.467 | D18: Meghan S | E18: Harapanahalli main | F18: 1st cs | G18: Himamnagar | H18: 177 | I18: https://maps.app.goo.gl/Z49PYuAGhwDWY59o9 | J18: Yes | K18: Residential | L18: Concrete | M18: 3.8 | N18: Good | O18: North | P18: Pavers | T18: -- | Z18: South | AA18: Pavers | AE18: Footpath not existing | AK18: North | AM18: 0.5 | AN18: 42573 | AO18: Maintenance | AP18: Some portion need cover slab and cleaning work | AQ18: South | AR18: 0.5 | AS18: 42573 | AT18: Good | AU18: Some portion need cover slab and cleaning work | AV18: Yes | AW18: PVC | AX18: 44034 | AY18: 0.225 | AZ18: Good | BA18: Yes | BB18: Good | BD18: LED- LT Line | BE18: Good
A19: 18 | B19: 46225.471 | E19: 1st Main | F19: 1st cs | G19: Himamnagar | H19: 150.7 | I19: https://maps.app.goo.gl/P4E51ihXg5LzbcHb7 | J19: Yes | K19: Residential | L19: Concrete | M19: 3.3 | N19: Good | O19: East | P19: Pavers | Q19: 1.3 | R19: 44034 | S19: Good | T19: Good | Z19: West | AA19: Pavers | AB19: 1.5 | AC19: 44034 | AD19: Good | AK19: East | AL19: FFL Gutter | AM19: 0.5 | AN19: 42573 | AO19: Good | AQ19: West | AR19: 0.5 | AS19: 42573 | AT19: Good | AV19: Yes | AW19: PVC | AX19: 44034 | AY19: 0.225 | AZ19: Good | BA19: Yes | BB19: Good | BD19: LED- LT Line | BE19: Good
A20: 19 | B20: 46225.478 | E20: 1st Main | F20: 2nd cs | G20: Himamnagar | H20: 45 | I20: https://maps.app.goo.gl/EeMgWCb33e8tLXHp9?g_st=ac | J20: No | K20: Residential | L20: Concrete | M20: 3 | N20: Good | O20: North | P20: Pavers | T20: Footpath not existing | Z20: n/a | AA20: n/a | AB20: 0 | AC20: n/a | AD20: n/a | AE20: Footpath not existing | AK20: North | AL20: FFL Gutter | AN20: 42573 | AO20: Good | AQ20: South | AU20: Pvc | AV20: Yes | AW20: PVC | AX20: 44399 | AY20: 0.225 | AZ20: Good | BA20: Yes | BB20: Good | BD20: LED- LT Line | BE20: Good
A21: 20 | B21: 46225.481 | E21: 1st Main | F21: 2nd cs | G21: Himamnagar | H21: 38.57 | I21: https://maps.app.goo.gl/dkhhZcoX8uvAdN9VA?g_st=ac | J21: No | K21: Conservency | L21: Concrete | M21: 3 | N21: Good | O21: n/a | P21: n/a | Q21: 0 | R21: n/a | S21: n/a | T21: Footpath not existing | Z21: n/a | AA21: n/a | AB21: 0 | AC21: n/a | AD21: n/a | AE21: Footpath not existing | AK21: East | AP21: Not in good condition | AU21: Existing not good | AV21: Yes | AW21: PVC | AX21: 42573 | AY21: 0.225 | AZ21: Required | BA21: Yes | BB21: Good | BD21: LED- LT Line | BE21: Good
A22: 21 | B22: 46225.489 | E22: 1st Main | F22: 2nd cs | G22: Himamnagar | H22: 18 | I22: https://maps.app.goo.gl/bnm4b5Ebtmqjf9tb6?g_st=ac | J22: No | K22: Conservency | L22: ?? | M22: 5 | N22: Good | O22: n/a | P22: n/a | Q22: 0 | R22: n/a | S22: n/a | T22: Footpath not existing | Z22: n/a | AA22: n/a | AB22: 0 | AC22: n/a | AD22: n/a | AE22: Footpath not existing | AK22: East | AP22: Not in good condition | AU22: Not existing | AV22: Yes | AW22: PVC | AX22: 42938 | AY22: 0.225 | AZ22: Good | BA22: Yes | BB22: Good | BD22: LED- LT Line | BE22: Required
A23: 22 | B23: 46225.493 | E23: Himamnagar | F23: Jandekatte road | G23: Himamnagar | H23: 38.19 | I23: https://maps.app.goo.gl/hXycaA2gv6ZKksSu9?g_st=ac | J23: Yes | K23: Conservency | L23: Concrete | M23: 3.1 | N23: Good | O23: East | P23: Pavers | T23: Not existing | Z23: n/a | AA23: n/a | AB23: 0 | AC23: n/a | AD23: n/a | AE23: Not existing | AK23: East | AL23: FFL Gutter | AP23: Not existing | AU23: Not existing | AV23: Yes | AW23: Stone | AX23: 42573 | AY23: Not sure | BA23: Yes | BB23: Good | BD23: LED- LT Line | BE23: Good
A24: 23 | B24: 46225.5 | E24: 1st main | F24: 2nd cs | H24: 140 | I24: https://maps.app.goo.gl/vzAk3Feg2GFbAALX8?g_st=ac | J24: No | K24: Residential | L24: Concrete | M24: 5 | N24: Good | O24: n/a | P24: n/a | Q24: 0 | R24: n/a | S24: n/a | T24: Footpath not existing | Z24: n/a | AA24: n/a | AB24: 0 | AC24: n/a | AD24: n/a | AE24: Footpath not existing | AK24: North | AL24: FFL Gutter | AM24: 0.5 | AN24: 42573 | AO24: Good | AQ24: South | AR24: 0.5 | AS24: 42573 | AT24: Good | AV24: Yes | AW24: Stone | AX24: 42573 | AY24: 0.225 | AZ24: Good | BA24: Yes | BB24: Good | BD24: LED- LT Line | BE24: Good
A25: 24 | B25: 46225.508 | E25: Bethur road | F25: Venkateswara temple | G25: Himamnagar | H25: 120 | I25: https://maps.app.goo.gl/rHKUZ1WpEvDxrwt37?g_st=ac | J25: Yes | K25: Residential | L25: Concrete | M25: 3.5 | N25: Good | O25: East | P25: Pavers | Q25: 1 | R25: 44034 | S25: Good | T25: -- | Z25: West | AA25: Pavers | AB25: 1 | AC25: 42573 | AK25: East | AL25: FFL Gutter | AM25: 0.5 | AN25: 42573 | AO25: Good | AQ25: West | AR25: 0.5 | AS25: 42573 | AT25: Good | AV25: Yes | AW25: Stone | AX25: 42573 | AY25: 0.225 | AZ25: Good | BA25: Yes | BB25: Good | BD25: LED- LT Line | BE25: Good
A26: 25 | B26: 46225.514 | E26: 4th | F26: 3rd cs | G26: Himamnagar | H26: 140 | I26: https://maps.app.goo.gl/ubvRsAKEZSBjDchK6?g_st=ac | J26: Damaged | K26: Residential | L26: Concrete | M26: 3.6 | N26: Good | O26: n/a | P26: n/a | Q26: 0 | R26: n/a | S26: n/a | T26: Not existing | Z26: n/a | AA26: n/a | AB26: 0 | AC26: n/a | AD26: n/a | AE26: Footpath not existing | AK26: East | AL26: FFL Gutter | AM26: 0.5 | AN26: 42573 | AO26: Good | AQ26: West | AR26: 0.5 | AS26: 42573 | AT26: Good | AV26: Yes | AW26: Stone | AX26: 42573 | AY26: 0.225 | AZ26: Good | BA26: Yes | BB26: Good | BD26: LED- LT Line | BE26: Good
A27: 26 | B27: 46225.516 | E27: 4th | F27: 4th cs | G27: Himamnagar | H27: 166 | I27: https://maps.app.goo.gl/mcZL1toBs3mcv96b7?g_st=ac | J27: Yes | K27: Residential | L27: Concrete | M27: 4 | N27: Good | O27: East | P27: Pavers | Q27: 1 | R27: 44034 | S27: Good | T27: Some portion need work | Z27: West | AA27: Pavers | AB27: 1 | AC27: 44034 | AD27: Good | AK27: East | AL27: FFL Gutter | AM27: 0.5 | AN27: 42573 | AO27: Good | AQ27: West | AR27: 0.5 | AS27: 42573 | AT27: Good | AV27: Yes | AW27: Stone | AX27: 42573 | AY27: 0.225 | AZ27: Good | BA27: Yes | BB27: Good | BD27: LED- LT Line | BE27: Required
A28: 27 | B28: 46225.521 | E28: 4th cs | F28: First cs | G28: Himamnagar | H28: 38 | I28: https://maps.app.goo.gl/cnSQbJ7whb2rrvoy7?g_st=ac | J28: No | K28: Conservency | L28: Concrete | M28: 4.6 | N28: Good | O28: n/a | P28: n/a | Q28: 0 | R28: n/a | S28: n/a | T28: Not existing | Z28: n/a | AA28: n/a | AB28: 0 | AC28: n/a | AD28: n/a | AE28: Not existing | AK28: East | AM28: 8 inch pipe | AN28: 42573 | AO28: Maintenance | AP28: Blockage | AQ28: South | AR28: 8 inch | AS28: 42573 | AT28: Maintenance | AU28: Blockage | AV28: No | BA28: Yes | BB28: Good | BD28: LED- LT Line | BE28: Maintenance
A29: 28 | B29: 46225.524 | E29: 3rd main | F29: 1st cross | G29: Himamnagar | H29: 33 | I29: https://maps.app.goo.gl/d65PjHrtMVSi6CnE9 | J29: No | K29: Conservency | L29: Concrete | M29: 4 | N29: Good | O29: n/a | P29: n/a | Q29: 0 | R29: n/a | S29: n/a | T29: Footpath not existing | Z29: n/a | AA29: n/a | AB29: 0 | AC29: n/a | AD29: n/a | AE29: Footpath not existing | AK29: North | AL29: FFL Gutter | AM29: 8 inch | AN29: 44399 | AO29: Good | AQ29: South | AR29: 8 inch | AS29: 44034 | AT29: Good | AU29: Good | AV29: No | AZ29: Additional Required | BA29: Yes | BB29: Good | BD29: Required | BE29: Required
A30: 29 | B30: 46225.528 | E30: 4th | F30: 2 nd | G30: Himamnagar | H30: 30 | I30: https://maps.app.goo.gl/zEFuScnT9n4Ubg5x9?g_st=ac | J30: No | K30: Conservency | L30: Concrete | M30: 2.8 | N30: Good | O30: n/a | P30: n/a | Q30: 0 | R30: n/a | S30: n/a | T30: Footpath not existing | Z30: n/a | AA30: n/a | AB30: 0 | AC30: n/a | AD30: n/a | AE30: Footpath not existing | AK30: North | AL30: FFL Gutter | AM30: 8 inch | AN30: 44399 | AO30: Maintenance | AP30: Blocked | AQ30: South | AR30: 8 inch | AS30: 44399 | AT30: Maintenance | AU30: Blocked | AV30: Yes | AW30: Stone | AX30: 42573 | AY30: 0.225 | AZ30: Good | BA30: No | BD30: Required | BE30: Required
A31: 30 | B31: 46225.531 | E31: 4th main | F31: 2nd concorence | G31: Himamnagar | H31: 42 | I31: https://maps.app.goo.gl/Dkoki7tnirN5Wh6D9?g_st=ac | J31: No | K31: Conservency | L31: Concrete | M31: 2.5 | N31: Good | O31: n/a | P31: n/a | Q31: 0 | R31: n/a | S31: n/a | T31: Footpath not existing | Z31: n/a | AA31: n/a | AB31: 0 | AC31: n/a | AD31: n/a | AE31: Noe xisting footpath | AK31: North | AL31: FFL Gutter | AM31: 0.5 | AN31: 42573 | AO31: Good | AQ31: South | AR31: 0.5 | AS31: 42573 | AT31: Good | AV31: Yes | AW31: Stone | AX31: 42573 | AY31: 0.225 | AZ31: Good | BA31: No | BB31: Required | BD31: Required | BE31: Required
A32: 31 | B32: 46225.534 | E32: 4th main | F32: 3rd concorence | G32: Himamnagar | H32: 35 | I32: https://maps.app.goo.gl/q8QPJYKpbUkf8bN69?g_st=ac | J32: No | K32: Conservency | L32: Concrete | M32: 4.6 | N32: Good | O32: North | P32: Pavers | T32: Footpath not existing | Z32: n/a | AA32: n/a | AB32: 0 | AC32: n/a | AD32: n/a | AE32: Footpath not existing | AK32: North | AL32: FFL Gutter | AM32: 8 inch | AN32: 44034 | AO32: Maintenance | AQ32: South | AR32: 8inch | AS32: 44034 | AT32: Good | AV32: No | BA32: Yes | BB32: Good | BD32: Required | BE32: Required
A33: 32 | B33: 46225.542 | E33: 4rd main | F33: 4rd concorence | G33: Himamnagarà | H33: 35 | I33: https://goo.gl/maps/Cao2Ews4qX328fuG8 | J33: No | K33: Conservency | L33: Concrete | M33: 2.5 | N33: Maintenance | O33: n/a | P33: n/a | Q33: 0 | R33: n/a | S33: n/a | T33: Footpath not existing | Z33: n/a | AA33: n/a | AB33: 0 | AC33: n/a | AD33: n/a | AE33: Footpath not existing | AF33: Pavement | AK33: North | AP33: Blocked | AQ33: South | AU33: Blocked | AV33: No | BA33: Yes | BD33: Required | BE33: Required
A34: 33 | B34: 46225.545 | E34: 3rd | F34: 3rd | G34: Himamnagarà | H34: 30 | I34: https://maps.app.goo.gl/VhZVs6i2W7bDAH5PA | J34: No | K34: Conservency | L34: Concrete | M34: 4.6 | N34: Good | O34: n/a | P34: n/a | Q34: 0 | R34: n/a | S34: n/a | T34: Footpath not existing | Z34: n/a | AA34: n/a | AB34: 0 | AC34: n/a | AD34: n/a | AE34: Footpath not existing | AK34: North | AL34: FFL Gutter | AM34: 8inch | AN34: 42573 | AO34: Required | AP34: Blocked | AQ34: South | AR34: 8inch | AS34: 42573 | AT34: Required | AU34: Blocked | AV34: No | BA34: Yes | BB34: Good | BD34: LED- LT Line | BE34: Good
A35: 34 | B35: 46225.548 | E35: 4th | F35: 4th | G35: Himamnagarà | H35: 34 | I35: https://maps.app.goo.gl/YvwVTMNqHoiWbcEw9?g_st=ac | J35: No | K35: Conservency | L35: Concrete | M35: 2.8 | N35: Required | O35: n/a | P35: n/a | Q35: 0 | R35: n/a | S35: n/a | T35: Footpath not existing | Z35: n/a | AA35: n/a | AB35: 0 | AC35: n/a | AD35: n/a | AE35: Footpath not existing | AK35: North | AL35: FFL Gutter | AM35: 8inch | AN35: 42573 | AO35: Required | AP35: Blocked | AQ35: South | AR35: 8inch | AS35: 42573 | AT35: Required | AU35: Blocked | AV35: No | BA35: No | BB35: Required | BD35: Required | BE35: Required
A36: 35 | B36: 46225.551 | E36: 3rd | F36: 3rd concorence | G36: Himamnagarà | H36: 30 | I36: https://maps.app.goo.gl/v2U46wWZGFd6wLKG6?g_st=ac | J36: No | K36: Conservency | L36: Concrete | M36: 2.2 | N36: Required | O36: n/a | P36: n/a | Q36: 0 | R36: n/a | S36: n/a | T36: Not existing | Z36: n/a | AA36: n/a | AB36: 0 | AC36: n/a | AD36: n/a | AE36: Not existing | AK36: North | AL36: FFL Gutter | AM36: 28inch | AN36: 42573 | AO36: Required | AQ36: South | AU36: Not existing | AV36: Yes | BA36: No | BB36: Required | BD36: Required | BE36: Required
A37: 36 | B37: 46225.554 | E37: 4th | F37: 5th | G37: Himamnagarà | H37: 36 | I37: https://maps.app.goo.gl/bt5zuDjDMEuLPn2D8?g_st=ac | J37: No | K37: Conservency | L37: Concrete | M37: 4.3 | N37: Good | O37: n/a | P37: n/a | Q37: 0 | R37: n/a | S37: n/a | T37: Not existing | Z37: n/a | AA37: n/a | AB37: 0 | AC37: n/a | AD37: n/a | AE37: Not existing | AK37: North | AP37: Swg not existing | AQ37: South | AU37: Seg not existing | AV37: No | AZ37: Additional Required | BA37: No | BB37: Good | BD37: LED- LT Line | BE37: Good
A38: 37 | B38: 46225.557 | E38: 3rd main | F38: 5th concorence | G38: Himamnagarà | H38: 36.78 | I38: https://maps.app.goo.gl/7dystqmVthHb8EGh7?g_st=ac | J38: No | K38: Conservency | L38: Concrete | M38: 4.3 | N38: Required | O38: n/a | P38: n/a | Q38: 0 | R38: n/a | S38: n/a | T38: Not existing | Z38: n/a | AA38: n/a | AB38: 0 | AC38: n/a | AD38: n/a | AE38: Footpath not existing | AK38: North | AL38: FFL Gutter | AM38: 8 inch | AN38: 42573 | AO38: Maintenance | AQ38: South | AR38: 8inch | AT38: Good | AV38: No | BA38: No | BB38: Required | BD38: Required | BE38: Required
A39: 38 | B39: 46225.56 | E39: 3rd main | F39: 6th | G39: Himamnagarà | H39: 36 | I39: https://maps.app.goo.gl/w6q13exaGSC6SCuy8 | J39: No | K39: Conservency | L39: Concrete | M39: 2.5 | N39: Required | O39: n/a | P39: n/a | Q39: 0 | R39: n/a | S39: n/a | T39: Footpath not existing | Z39: n/a | AA39: n/a | AB39: 0 | AC39: n/a | AD39: n/a | AE39: Footpath not existing | AK39: North | AL39: FFL Gutter | AM39: 8inch | AN39: 42573 | AO39: Required | AQ39: South | AR39: 8inch | AS39: 42573 | AT39: Required | AV39: Yes | AW39: Stone | AX39: 42573 | AY39: 0.225 | AZ39: Required | BA39: Yes | BB39: Required | BD39: LED- LT Line | BE39: Required
A40: 39 | B40: 46225.563 | E40: 4th | F40: 6th | G40: Himamnagarà | H40: 35 | I40: https://maps.app.goo.gl/RFgRXp7auaoay39T9 | J40: Yes | K40: Conservency | L40: Concrete | M40: 2.5 | N40: Good | O40: n/a | P40: n/a | Q40: 0 | R40: n/a | S40: n/a | T40: Not existing | Z40: n/a | AA40: n/a | AB40: 0 | AC40: n/a | AD40: n/a | AE40: Not existing | AK40: North | AL40: FFL Gutter | AM40: 8inch | AN40: 42573 | AO40: Required | AQ40: South | AR40: 8inch | AS40: 42573 | AT40: Required | AV40: Yes | AW40: Stone | AX40: 42573 | AY40: 0.225 | AZ40: Good | BA40: No | BB40: Required | BD40: LED- LT Line | BE40: Required
...

Sheet DS
B1: Ward No: | D1: ="03" -> 03
B2: Ward Name: | D2: Siddrameshwara badavane, Mandakibatti Layout, AK Colony
B3: Total Number of Roads | E3: 93 | F3: nos
B4: Total Road Length | D4: ='Form responses 1'!$I$112 | F4: km
D5: nos | E5: Length | F5: Area | G5: Action | H5: Std Rate | I5: Estimation | J5: Notes
C6: unit | D6: # | E6: m | F6: sqm | H6: INR | I6: INR
A7: I. Road | B7: Rd.Sign | C7: Yes | D7: =COUNTIF('Form responses 1'!K2:K94,C7) -> 0 | F7: na
C8: No | D8: =COUNTIF(#REF!,C8) -> 28
C9: Damaged | D9: =COUNTIF('Form responses 1'!K2:K94,C9) -> 0
B10: Road Type | C10: Main Rd | D10: =COUNTIF('Form responses 1'!$L$2:$L$94,C10) -> 0 | F10: {=SUM(IF('Form responses 1'!$L$2:$L$94 = C10,'Form responses 1'!$I$2:$I$94*'Form responses 1'!$N$2:$N$94, ""))} -> 0
C11: Comercial | D11: =COUNTIF('Form responses 1'!$L$2:$L$94,C11) -> 0 | F11: {=SUM(IF('Form responses 1'!$L$2:$L$94 = C11,'Form responses 1'!$I$2:$I$94*'Form responses 1'!$N$2:$N$94, ""))} -> 0
C12: Residential | D12: =COUNTIF('Form responses 1'!$L$2:$L$94,C12) -> 0 | F12: {=SUM(IF('Form responses 1'!$L$2:$L$94 = C12,'Form responses 1'!$I$2:$I$94*'Form responses 1'!$N$2:$N$94, ""))} -> 0
C13: Conservency | D13: =COUNTIF('Form responses 1'!$L$2:$L$94,C13) -> 0 | F13: {=SUM(IF('Form responses 1'!$L$2:$L$94 = C13,'Form responses 1'!$I$2:$I$94*'Form responses 1'!$N$2:$N$94, ""))} -> 0
B14: Road Material | C14: Concrete | D14: =COUNTIF('Form responses 1'!$M$2:$M$94,C14) -> 0 | F14: {=SUM(IF('Form responses 1'!$M$2:$M$94 = C14,'Form responses 1'!$I$2:$I$94*'Form responses 1'!$N$2:$N$94, ""))} -> 0
C15: Gravell | D15: =COUNTIF('Form responses 1'!$M$2:$M$94,C15) -> 0 | F15: {=SUM(IF('Form responses 1'!$M$2:$M$94 = C15,'Form responses 1'!$I$2:$I$94*'Form responses 1'!$N$2:$N$94, ""))} -> 0 | G15: Convert to concrete | H15: 2000 | I15: =H15*F15 -> 0
C16: Mud | D16: =COUNTIF('Form responses 1'!$M$2:$M$94,C16) -> 0 | F16: {=SUM(IF('Form responses 1'!$M$2:$M$94 = C16,'Form responses 1'!$I$2:$I$94*'Form responses 1'!$N$2:$N$94, ""))} -> 0 | G16: Convert to concrete | H16: 2000 | I16: =H16*F16 -> 0
C17: Tar | D17: =COUNTIF('Form responses 1'!$M$2:$M$94,C17) -> 0 | F17: {=SUM(IF('Form responses 1'!$M$2:$M$94 = C17,'Form responses 1'!$I$2:$I$94*'Form responses 1'!$N$2:$N$94, ""))} -> 0
C18: White Topping | D18: =COUNTIF('Form responses 1'!$M$2:$M$94,C18) -> 0 | F18: {=SUM(IF('Form responses 1'!$M$2:$M$94 = C18,'Form responses 1'!$I$2:$I$94*'Form responses 1'!$N$2:$N$94, ""))} -> 0
B19: Condition | C19: Good
C20: Required
C21: Outdated
C22: Maintenance
C23: n/a
A24: II. Attachment (N,S,E,W) | B24: Type (N/S) + (E/W) | C24: Pavers | D24: =COUNTIF('Form responses 1'!$Q$2:$Q$94,C24)+COUNTIF('Form responses 1'!$AB$2:$AB$94,C24) -> 0
C25: Pavers (Elevated) | D25: =COUNTIF('Form responses 1'!$Q$2:$Q$94,C25)+COUNTIF('Form responses 1'!$AB$2:$AB$94,C25) -> 0
C26: Pavers Ramp (Elevated) | D26: =COUNTIF('Form responses 1'!$Q$2:$Q$94,C26)+COUNTIF('Form responses 1'!$AB$2:$AB$94,C26) -> 0
C27: Divider (Concrete) | D27: =COUNTIF('Form responses 1'!$Q$2:$Q$94,C27)+COUNTIF('Form responses 1'!$AB$2:$AB$94,C27) -> 0
C28: Divider (Planter) | D28: =COUNTIF('Form responses 1'!$Q$2:$Q$94,C28)+COUNTIF('Form responses 1'!$AB$2:$AB$94,C28) -> 0
C29: Curb (Planterbox) | D29: =COUNTIF('Form responses 1'!$Q$2:$Q$94,C29)+COUNTIF('Form responses 1'!$AB$2:$AB$94,C29) -> 0
C30: Exposed Soil | D30: =COUNTIF('Form responses 1'!$Q$2:$Q$94,C30)+COUNTIF('Form responses 1'!$AB$2:$AB$94,C30) -> 0
C31: Bund | D31: =COUNTIF('Form responses 1'!$Q$2:$Q$94,C31)+COUNTIF('Form responses 1'!$AB$2:$AB$94,C31) -> 0
C32: Bund | D32: =COUNTIF('Form responses 1'!$Q$2:$Q$94,C32)+COUNTIF('Form responses 1'!$AB$2:$AB$94,C32) -> 0
C33: n/a | D33: =COUNTIF('Form responses 1'!$Q$2:$Q$94,C33)+COUNTIF('Form responses 1'!$AB$2:$AB$94,C33) -> 0
B34: Condition | C34: Good
C35: Required
C36: Additional Required
C37: Outdated
C38: Maintenance
C39: n/a
A40: III. SWG (N,S,E,W) | C40: FFL Gutter
...

Sheet Sheet1
A1: ROAD SURVEY — DVG SOUTH CONSTITUENCY — WARD NO. 11
A2: I. | B2: II. | F2: III. | G2: IV. | H2: V. | I2: VI. ROAD ONLY | AJ2: VI. STORM WATER GUTTER | AU2: VII. UNDERGROUND DRAINAGE | AZ2: VIIII. JALASIRI | BC2: IX. ELECTRICAL LIGHTING
A3: # | B3: Road Name | C3: Volunteer | D3: Main | E3: Cross | F3: Area Name | G3: Dist. | H3: Loc | I3: ROAD | N3: Attachement I (N/E) | Y3: Attachement II (S/W) | AJ3: (N/E) | AP3: (S/W) | AU3: Existing | AV3: Type | AX3: Pipe Dia | AY3: Condition | AZ3: Existing | BA3: Condition | BB3: Note | BC3: Light Type | BD3: Condition
I4: Road Sign | J4: Use | K4: Material | L4: Width | M4: Condition | N4: Side | O4: Attachment 1 | P4: Width | Q4: Dated | R4: Condition | S4: Notes | T4: Attachment 2 | U4: Width | V4: Dated | W4: Condition | X4: Notes | Y4: Side | Z4: Attachment 1 | AA4: length*Width | AB4: Dated | AC4: Condition | AD4: Notes | AE4: Attachment 2 | AF4: Width | AG4: Dated | AH4: Condition | AI4: Notes | AJ4: Side | AL4: Width | AM4: Dated | AN4: Condition | AO4: Notes | AP4: Side | AQ4: Width | AR4: Dated | AS4: Condition | AT4: Notes | AW4: Date
G5: m | L5: m | P5: m | U5: m | Z5: x | AA5: m | AF5: m | AL5: m | AQ5: m | AX5: mm
A6: 1 | B6: Kalikadevi Road | C6: Aktar Raza | H6: https://www.google.com/maps/search/?api=1&query=14.4732522,75.9192997 | I6: No | J6: Comercial | K6: Concrete | N6: North | O6: Pavement | T6: Pavement (Elevated) | AU6: Yes
A7: 2 | B7: charlie pailwan road | C7: Aktar Raza | F7: -- | G7: 150 | H7: https://www.google.com/maps/search/?api=1&query=14.4751098,75.9190651 | I7: No | J7: Comercial | K7: Concrete | L7: 8.6 | M7: Maintiance | N7: North | O7: Pavement | P7: 1.3 | Q7: 2022 | R7: Good | S7: lights and curb stone and paints | T7: Pevement Ramp (Elevated) | U7: 1.3 | V7: 2022 | W7: Good | X7: paints and marking, signages | Y7: South | Z7: Planterbox (Curb) | AA7: 2.3*1.2 | AB7: 2022 | AC7: Required | AD7: paints | AE7: Planterbox (Curb) | AF7: 1.8m | AG7: 2022 | AH7: Required | AI7: planter box with decorative arts neefed | AJ7: North | AK7: No Gutter | AL7: no | AM7: no | AN7: N/A | AO7: not need gutter | AP7: NA | AQ7: NA | AR7: NA | AS7: N/A | AT7: NA | AU7: Yes | AV7: Concrete | AW7: 2021 | AX7: 300mm | AY7: Good | AZ7: Yes | BA7: good | BB7: issues HSC service related | BC7: LED- Pole | BD7: maintainence need
A8: 3 | B8: aazam MAASJID RD | C8: Aktar Raza | E8: 2ND | F8: Nasrajpete | G8: 140 | H8: https://www.google.com/maps/search/?api=1&query=14.4739541,75.9191241 | I8: Yes | J8: Residential | K8: Concrete | L8: 5.5 | M8: Good | N8: East | O8: Pavement | P8: 0.6 | Q8: 2016 | R8: Good | T8: N/A | U8: na | V8: NA | W8: N/A | X8: NA | Y8: West | Z8: Pavement | AA8: 1.2 | AB8: NA | AC8: Good | AD8: NA | AE8: N/A | AF8: NA | AG8: NA | AH8: N/A | AI8: NA | AK8: Elevated Gutter | AL8: 0.6 | AM8: 2016 | AN8: Good | AO8: HOUSE SERVICE CONNECTION DAMAGED | AP8: Elevated Gutter | AQ8: 0.6 | AS8: Good | AT8: NA | AU8: Yes | AV8: Stone | AW8: -- | AX8: 225 | AY8: Outdated | AZ8: Yes | BA8: -- | BB8: --
A9: 4 | B9: N R PETE 1ST CROSS | C9: Aktar Raza | E9: 1ST | F9: Nasrajpete | H9: https://www.google.com/maps/search/?api=1&query=14.473621,75.9188915 | I9: Yes | J9: Residential | K9: Concrete | L9: 4.4 | M9: Good | N9: North | O9: N/A | P9: NA | Q9: 2006 | R9: Good | S9: GOOD | T9: N/A | W9: N/A | Z9: N/A | AC9: N/A | AK9: FFL Gutter | AL9: 0.45 | AM9: 2006 | AN9: Good | AO9: MAINTAINENCE | AP9: FFL Gutter | AQ9: 0.45 | AR9: 2006 | AS9: Good | AT9: NA | AU9: Yes | AV9: Stone | AW9: 2006 | AX9: 225 | AY9: Outdated | AZ9: Yes | BA9: GOOD | BB9: MAINTAINENCE | BC9: LED- Pole | BD9: MAINTAINENSE
A10: 5 | B10: NR PETE CONSERVENCY IN BETWEEN MAIN ROAD AND 1ST CROSS | C10: Aktar Raza | F10: Nasrajpete | H10: https://www.google.com/maps/search/?api=1&query=14.4758399,75.9236194 | I10: Yes | J10: Residential | K10: Concrete | L10: 4.2 | M10: Good | N10: North | O10: N/A | P10: NA | Q10: 2006 | R10: Good | S10: GOOD | T10: N/A | W10: N/A | Z10: N/A | AC10: N/A | AE10: N/A | AH10: N/A | AL10: 0.45 | AM10: 2006 | AN10: Maintiance | AO10: MAINTAINENCE | AP10: FFL Gutter | AQ10: 0.45 | AR10: 2006 | AS10: Maintiance | AT10: Cover Slab req | AU10: Yes | AV10: Stone | AW10: 2006 | AX10: 225 | AY10: Outdated | AZ10: Yes | BA10: GOOD | BC10: LED- Pole | BD10: MAINTAINENSE
A11: 6 | B11: N R PETE 3RD CROSS | C11: Aktar Raza | E11: 3RD | F11: Nasrajpete | H11: https://www.google.com/maps/search/?api=1&query=14.4766888,75.9286087 | I11: Yes | J11: Residential | K11: Concrete | L11: 4 | M11: Good | N11: North | O11: N/A | P11: NA | Q11: 2006 | R11: Maintiance | S11: RESTORATION REQIRED | T11: N/A | U11: NA | V11: NA | W11: N/A | AE11: N/A | AH11: N/A | AJ11: North | AK11: FFL Gutter | AL11: 0.45 | AM11: 2006 | AN11: Good | AO11: MAINTAINENCE COVERING SLABS IS REQUIRED | AP11: FFL Gutter | AQ11: 0.45 | AR11: 2006 | AS11: Maintiance | AT11: Cover Slab req | AU11: Yes | AV11: Stone | AW11: 2006 | AX11: 225 | AY11: Outdated | AZ11: Yes | BA11: HOUSEHOLD SERVICE CONNECTION NEED | BB11: MAINTAINENCE | BC11: LED- Pole | BD11: MAINTAINENCE
A12: 7 | B12: CONSERVENCY IN BETWEEN 3RD AND 4TH | C12: Aktar Raza | F12: Nasrajpete | H12: https://www.google.com/maps/search/?api=1&query=14.4741054,75.9205325 | I12: No | J12: Residential | K12: Concrete | L12: 2.5 | M12: Good | N12: North | O12: N/A | R12: N/A | T12: N/A | W12: N/A | Z12: N/A | AC12: N/A | AE12: N/A | AH12: N/A | AK12: No Gutter | AL12: NA | AN12: N/A | AU12: Yes | AV12: Stone | AW12: 2021 | AX12: 225 | AY12: Maintiance | AZ12: Yes | BB12: GOOD | BC12: NA
A13: 8 | B13: N r pet 4th cross | E13: 4th cross | F13: Nasrajpete | G13: 3.7 | I13: Yes | J13: Residential | K13: Concrete | L13: 3.7 | M13: Maintiance | N13: North | O13: N/A | P13: 1 | Q13: 2023 | R13: Maintenance | T13: Pavement | U13: 1.4 | V13: 2023 | W13: Good | AK13: FFL | AL13: 0.6 | AM13: 2006 | AN13: Maintenance | AQ13: 0.6 | AR13: 2006 | AS13: Maintenance | AV13: Stone | AY13: Outdated | AZ13: Yes | BB13: Good | BC13: Led
A14: 9 | B14: Nasrajpet concorence 1 | I14: No | J14: Residential | K14: Concrete | L14: 2.3 | M14: Good | N14: North | O14: N/A | T14: NA | AK14: NA | AV14: Stone | AY14: Outdated | AZ14: Yes | BB14: To be maintain | BC14: NA | BD14: No street lights
A15: 10 | B15: Concerence between 4th cross NR pet and KR road | I15: Yes | J15: Residential | K15: Concrete | L15: 2.7 | M15: Maintiance | N15: North | O15: N/A | AK15: FFL | AL15: 0.6 | AM15: 2006 | AN15: Good | AP15: FFL | AQ15: 0.6 | AR15: 2006 | AS15: Maintenance | AV15: Stone | AZ15: Yes | BA15: Good | BB15: Hsd maintenance required | BC15: Led | BD15: Good
A16: 11 | B16: Imam nagar 1st cross | E16: 1st cross | F16: Imam nagar | I16: Yes | J16: Residential | K16: Concrete | L16: 5.4 | M16: Maintiance | N16: North | O16: N/A | Q16: 2011 | AK16: FFL | AL16: 0.6 | AM16: 2016 | AN16: Maintenance | AP16: FFL | AQ16: 0.6 | AR16: 2006 | AS16: Maintenance | AT16: Cleaning required | AV16: Concrete | AW16: 2016 | AY16: Cleaning required | AZ16: Yes | BB16: HSC maintenance | BC16: LED | BD16: Good
A17: 12 | B17: Imam nagar 2nd cross | I17: Yes | J17: Residential | K17: Concrete | L17: 3.1 | M17: Good | N17: North | O17: Pavement | P17: 1.5 | Q17: 2023 | Y17: South | Z17: Pavement | AA17: 1.3 | AB17: 2023 | AC17: Good | AJ17: North | AK17: Elevated | AL17: 0.7 | AM17: 2023 | AN17: Maintenance | AP17: Elevated | AQ17: 0.7 | AR17: 2023 | AS17: Maintenance | AV17: Concrete | AZ17: Yes | BB17: Water not coming | BC17: Led | BD17: Good
A18: 13 | B18: Main Concerence behind imam nagar 1 st cross | I18: No | J18: R-Conservency | K18: Concrete | L18: 5 | M18: Good | N18: North | O18: NA | AK18: FFL | AL18: 0.5 | AM18: 2016 | AN18: Outdated | AO18: Flood condition on road during rain | AP18: FFL | AQ18: 0.5 | AR18: 2016 | AT18: New line required | AV18: Stone | AW18: 2006 | AY18: Replacement of Ugd required | AZ18: Yes | BB18: Connection not there
A19: 14 | B19: Concerence 1 in concrence 1st main | J19: R-Conservency | K19: Concrete | L19: 1.66 | M19: Good | N19: North | AV19: Stone | AW19: 2006 | AY19: Replacement Ugd required | AZ19: Yes | BB19: Connection not there | BC19: NA | BD19: Maintenance required
A20: 15 | B20: Concerence 2 | I20: No | J20: R-Conservency | K20: Concrete | L20: 3 | M20: Good | N20: North | AJ20: NA | AT20: Storm water drain required | AU20: Yes | AV20: Stone | AW20: 2006 | AY20: Replacement
A21: 16 | B21: Imam nagar jhandekatha road | I21: Yes | J21: Residential | K21: Concrete | L21: 5 | M21: Maintiance | N21: North | AK21: Elevated | AL21: 0.6 | AM21: 2022 | AN21: Maintenance | AP21: Elevated | AQ21: 0.65 | AR21: 2020 | AS21: Maintenance | AV21: Stone | AW21: 2006 | AZ21: Yes | BB21: Connection not provided | BC21: Yes | BD21: Good
B22: rOAD 1
G23: 162
