Workbook

Sheet Form responses 1
A1: Timestamp | B1: Email address | C1: Surveyor Name | D1: Column 58 | E1: Road Name (Main) | F1: Road Name (Cross) | G1: Area Name | H1: Dist. (m) | I1: Location (Google Maps link) | J1: Road Sign | K1: Use | L1: Material | M1: Width (m) | N1: Road Condition | O1: Side (N/E) | P1: Attachment 1 Type | Q1: Attachment 1 Width (m) | R1: Attachment 1 Dated | S1: Attachment 1 Condition | T1: Attachment 1 Notes | U1: Attachment 2 Type | V1: Attachment 2 Width (m) | W1: Attachment 2 Dated | X1: Attachment 2 Condition | Y1: Attachment 2 Notes | Z1: Side (S/W) | AA1: Attachment 1 Type (S/W) | AB1: Attachment 1 Width (m) (S/W) | AC1: Attachment 1 Dated (S/W) | AD1: Attachment 1 Condition (S/W) | AE1: Attachment 1 Notes (S/W) | AF1: Attachment 2 Type (S/W) | AG1: Attachment 2 Width (m) (S/W) | AH1: Attachment 2 Dated (S/W) | AI1: Attachment 2 Condition (S/W) | AJ1: Attachment 2 Notes (S/W) | AK1: SWG Side (N/E) | AL1: SWG Type (N/E) | AM1: SWG Width (m) (N/E) | AN1: SWG Dated (N/E) | AO1: SWG Condition (N/E) | AP1: SWG Notes (N/E) | AQ1: SWG Side (S/W) | AR1: SWG Width (m) (S/W) | AS1: SWG Dated (S/W) | AT1: SWG Condition (S/W) | AU1: SWG Notes (S/W) | AV1: UGD Existing | AW1: UGD Type | AX1: UGD Date | AY1: UGD Pipe Dia (mm) | AZ1: UGD Condition | BA1: Jalasiri Existing | BB1: Jalasiri Condition | BC1: Jalasiri Note | BD1: Light Type | BE1: Electrical Condition | BF1: Electrical Notes
A2: 46225.49 | C2: Soumya s s | D2: 1 | E2: 1st main | F2: 1st cross | G2: Azaad nagar | H2: 263 | I2: https://maps.app.goo.gl/HyYPiq6CU7WYDUio7?g_st=ac | J2: Yes | K2: Comercial | L2: Concrete | M2: 5.5 | N2: Good | O2: North | P2: Bund | Q2: ?? | R2: 45495 | S2: Good | T2: -- | Z2: South | AA2: Bund | AB2: 1.25 | AC2: 45495 | AD2: Required | AE2: Bund pavement connected to road pavement required | AK2: North | AL2: FFL Gutter | AM2: 0.9 | AN2: 45495 | AO2: Good | AP2: -- | AQ2: South | AR2: 1 | AS2: 45495 | AT2: Good | AU2: -- | AV2: Yes | AW2: PVC | AX2: 45495 | AY2: 0.15 | AZ2: Good | BA2: Yes | BB2: Maintenance | BC2: Jalasiri is their but no water | BD2: LED- Pole | BE2: Good
A3: 46225.496 | C3: Soumya s s | D3: 2 | E3: 1st | F3: 1st cross | G3: Bidi layout | H3: 119 | I3: https://maps.app.goo.gl/cR9D6bG4V1ae3t969 | J3: No | K3: Residential | L3: Concrete | M3: 4 | N3: Good | O3: East | P3: Pavers (Elevated) | Q3: 0.6 | R3: 45495 | S3: Required | T3: Pavement attached to road pavement required | Z3: West | AA3: Pavers (Elevated) | AB3: 0.6 | AC3: 45495 | AD3: Required | AE3: -- | AK3: East | AL3: FFL Gutter | AM3: 0.6 | AN3: 45495 | AO3: Good | AP3: -- | AQ3: West | AR3: 0.6 | AS3: 45495 | AT3: Good | AU3: -- | AV3: Yes | AW3: PVC | AX3: 45495 | AY3: 0.15 | AZ3: Good | BA3: Yes | BB3: Maintenance | BC3: Jalasiri outdated | BD3: LED- Pole | BE3: Good
A4: 46225.499 | C4: Soumya s s | D4: 3 | E4: 1st main | F4: 2nd cross | G4: Bidi layout | H4: 74 | I4: https://maps.app.goo.gl/pLHN18cH3mcV2gzw9 | J4: Yes | K4: Residential | L4: Concrete | M4: 4 | N4: Good | O4: North | P4: Divider (Concrete) | Q4: 0.9 | R4: 45495 | S4: Good | T4: -- | Z4: South | AA4: Divider (Concrete) | AB4: 0.9 | AC4: 45495 | AD4: Good | AE4: -- | AK4: North | AL4: FFL Gutter | AM4: 0.9 | AN4: 45495 | AO4: Good | AP4: -- | AQ4: South | AR4: 0.9 | AS4: 45495 | AT4: Good | AU4: -- | AV4: Yes | AW4: PVC | AX4: 45495 | AY4: 0.15 | AZ4: Good | BA4: Yes | BB4: Maintenance | BC4: -- | BD4: LED- Pole | BE4: Good
A5: 46225.502 | C5: Soumya s s | D5: 4 | E5: 1st main | F5: 3rd cross | G5: Bidi layout | H5: 71 | I5: https://maps.app.goo.gl/Gp5QtpNYPznhNUFv7 | J5: Yes | K5: Residential | L5: Concrete | M5: 4.3 | N5: Good | O5: North | P5: Pavers | Q5: 1 | R5: 45495 | S5: Good | T5: -- | Z5: South | AA5: Divider (Concrete) | AB5: 1 | AC5: 45495 | AD5: Good | AE5: -- | AK5: North | AL5: FFL Gutter | AM5: 0.9 | AN5: 45129 | AO5: Good | AP5: -- | AQ5: South | AR5: 0.9 | AS5: 45129 | AT5: Good | AU5: -- | AV5: Yes | AW5: PVC | AX5: 45495 | AY5: 0.15 | AZ5: Good | BA5: Yes | BB5: Maintenance | BC5: Jalasiri existed but water is not comming | BD5: LED- Pole | BE5: Good
A6: 46225.505 | C6: Soumya s s | D6: 5 | E6: 1st main | F6: 4th cross | G6: Bidi layout | H6: 76 | I6: https://maps.app.goo.gl/73voYDzBPYqGWaVC6 | J6: Yes | K6: Residential | L6: Concrete | M6: 4.2 | N6: Good | O6: North | P6: Pavers | Q6: 1.3 | R6: 45495 | S6: Good | T6: -- | Z6: South | AA6: Pavers | AB6: 1.3 | AC6: 45495 | AD6: Good | AE6: -- | AK6: North | AL6: FFL Gutter | AM6: 0.9 | AN6: 45495 | AO6: Good | AP6: -- | AQ6: South | AR6: 0.9 | AS6: 45495 | AT6: Good | AU6: -- | AV6: Yes | AW6: PVC | AX6: 45495 | AY6: 0.15 | AZ6: Good | BA6: Yes | BB6: Maintenance | BC6: Jalasiri existed but no water supply | BD6: LED- Pole | BE6: Good
A7: 46225.509 | C7: Soumya s s | D7: 6 | E7: 1st main | F7: 5th cross | G7: Bidi layout | H7: 111 | I7: https://maps.app.goo.gl/otZnEJ3NMnsQtbne7?g_st=ac | J7: Yes | K7: Residential | L7: Concrete | M7: 4.3 | N7: Good | O7: North | P7: Bund | Q7: 1 | R7: 45495 | S7: Good | T7: -- | Z7: South | AA7: Bund | AB7: 1 | AC7: 45495 | AD7: Good | AE7: -- | AK7: North | AL7: FFL Gutter | AM7: 0.9 | AN7: 45495 | AO7: Good | AP7: -- | AQ7: South | AR7: 0.9 | AS7: 45495 | AT7: Good | AU7: -- | AV7: Yes | AW7: PVC | AX7: 45495 | AY7: 0.15 | AZ7: Good | BA7: Yes | BB7: Maintenance | BC7: Jalasiri existed but no water supply | BD7: LED- Pole | BE7: Good
A8: 46225.527 | C8: Soumya s s | D8: 7 | E8: 1st main | F8: 6th cross | G8: Bidi layout | H8: 273 | I8: https://maps.app.goo.gl/ivVsEADrkyEbaTQx5 | J8: Yes | K8: Residential | L8: Concrete | M8: 5.5 | N8: Good | O8: North | P8: Divider (Concrete) | Q8: 2 | R8: 2024 | S8: Good | T8: -- | Z8: South | AA8: Divider (Concrete) | AB8: 2 | AC8: 2024 | AD8: Good | AE8: -- | AK8: North | AL8: FFL Gutter | AM8: 0.9 | AN8: 2024 | AO8: Good | AP8: -- | AQ8: South | AR8: 0.9 | AS8: 2024 | AT8: Good | AU8: -- | AV8: Yes | AW8: PVC | AX8: 2024 | AY8: 0.15 | AZ8: Good | BA8: Yes | BB8: Maintenance | BC8: Jalasiri existed but no water supply | BD8: LED- Pole | BE8: Good
A9: 46225.53 | C9: Soumya s s | D9: 8 | E9: 1st | F9: 7th cross | G9: Bidi layout | H9: 114 | I9: https://maps.app.goo.gl/Df5abVQ39khu3Uuh8 | J9: Yes | K9: Residential | L9: Concrete | M9: 4.1 | N9: Good | O9: North | P9: Bund | Q9: 0 | R9: 2024 | S9: Required | T9: -- | Z9: South | AA9: Bund | AB9: 0 | AC9: 2014 | AD9: Required | AE9: -- | AK9: North | AL9: FFL Gutter | AM9: 0.9 | AN9: 2014 | AO9: Good | AP9: -- | AQ9: South | AR9: 0.9 | AS9: 2024 | AT9: Good | AU9: -- | AV9: Yes | AW9: PVC | AX9: 2014 | AY9: 0.15 | AZ9: Good | BA9: Yes | BB9: Maintenance | BC9: Jalasiri existed but no water supply | BD9: LED- Pole | BE9: Good
A10: 46225.533 | C10: Soumya ss | D10: 9 | E10: 1 st main | F10: 8 cross | G10: Bidi layout | H10: 115 | I10: https://maps.app.goo.gl/UXn4hyJBM4gBniBG7 | J10: Yes | K10: Residential | L10: Concrete | M10: 4.3 | N10: Good | O10: North | P10: Divider (Concrete) | Q10: 0.7 | R10: 2025 | S10: Good | T10: -- | Z10: South | AA10: Divider (Concrete) | AB10: 0.9 | AC10: 2024 | AE10: -- | AK10: North | AL10: FFL Gutter | AM10: 0.9 | AN10: 2024 | AO10: Good | AP10: -- | AQ10: South | AR10: 0.9 | AS10: 2024 | AT10: Good | AU10: -- | AV10: Yes | AW10: PVC | AX10: 2014 | AY10: 0.15 | AZ10: Good | BA10: Yes | BB10: Maintenance | BC10: Jalasiri existed no water supply | BD10: LED- Pole | BE10: Good
A11: 46225.536 | C11: Soumya s s | D11: 10 | E11: 1st main | F11: 9th cross | G11: Bidi layout | H11: 121 | I11: https://maps.app.goo.gl/JUJn9VHdQRsdEYSZA?g_st=ac | J11: Yes | K11: Residential | L11: Concrete | M11: 4.2 | N11: Good | O11: North | P11: Bund | Q11: 0.9 | R11: 2024 | S11: Good | T11: -- | Z11: South | AA11: Bund | AB11: 0.9 | AC11: 2024 | AD11: Good | AE11: -- | AK11: North | AL11: FFL Gutter | AM11: 0.9 | AN11: 2024 | AO11: Good | AP11: -- | AQ11: South | AR11: 0.9 | AS11: 2024 | AT11: Good | AU11: -- | AV11: Yes | AW11: PVC | AX11: 2024 | AY11: 0.15 | AZ11: Good | BA11: Yes | BB11: Maintenance | BC11: Jalasiri existed but no water supply | BD11: LED- Pole | BE11: Good
A12: 46225.546 | C12: Soumya s s | D12: 11 | E12: 1st main | F12: 10th cross | G12: Bidi layout | H12: 301 | I12: https://maps.app.goo.gl/nkQ4fBa1y3aMdDz49 | J12: Yes | K12: Residential | L12: Concrete | M12: 6.2 | N12: Good | O12: North | P12: Divider (Concrete) | Q12: 2.7 | R12: 2024 | S12: Good | T12: -- | Z12: South | AA12: Divider (Concrete) | AB12: 0.5 | AC12: 2024 | AD12: Required | AE12: -- | AK12: North | AL12: FFL Gutter | AM12: 0.9 | AN12: 2024 | AO12: Good | AP12: -- | AQ12: South | AR12: 0.9 | AS12: 2024 | AT12: Good | AU12: -- | AV12: Yes | AW12: PVC | AX12: 2024 | AY12: 0.15 | AZ12: Good | BA12: Yes | BB12: Maintenance | BC12: Jalasiri existed but no water supply | BD12: LED- Pole | BE12: Good
A13: 46225.549 | C13: Soumya s s | D13: 12 | E13: 1st main | F13: 11th cross | G13: Bidi layout | H13: 125 | I13: https://maps.app.goo.gl/5qn9egSj5c6xphs1A | J13: Yes | K13: Residential | L13: Concrete | M13: 4.5 | N13: Good | O13: North | P13: Bund | Q13: 0.9 | R13: 2024 | S13: Required | T13: -- | Z13: South | AA13: Bund | AB13: 0.9 | AC13: 2024 | AD13: Good | AE13: -- | AK13: North | AL13: FFL Gutter | AM13: 0.9 | AN13: 2024 | AO13: Good | AP13: -- | AQ13: South | AR13: 0.9 | AS13: 2024 | AT13: Good | AU13: -- | AV13: Yes | AW13: PVC | AX13: 2024 | AY13: 0.15 | AZ13: Good | BA13: Yes | BB13: Good | BC13: Jalasiri existed but no water supply | BD13: LED- Pole | BE13: Good
A14: 46225.552 | C14: Soumya s s | D14: 13 | E14: 1 st main | F14: 12 cross | G14: Bidi layout | H14: 130 | I14: https://maps.app.goo.gl/8v5xbD6h6CkqVHNF6?g_st=ac | J14: Yes | K14: Residential | L14: Concrete | M14: 4 | N14: Good | O14: North | P14: Divider (Concrete) | Q14: 1.3 | R14: 2024 | S14: Good | T14: -- | Z14: South | AA14: Divider (Concrete) | AB14: 1.3 | AC14: 2024 | AD14: Good | AE14: -- | AK14: North | AL14: FFL Gutter | AM14: 1.3 | AN14: 2024 | AO14: Good | AP14: -- | AQ14: South | AR14: 0.9 | AS14: 2024 | AT14: Good | AU14: -- | AV14: Yes | AW14: PVC | AX14: 2024 | AY14: 0.15 | AZ14: Good | BA14: Yes | BB14: Maintenance | BC14: Jalasiri existed but no water supply | BD14: LED- Pole | BE14: Good
A15: 46225.554 | C15: Soumya ss | D15: 14 | E15: 1st main | F15: 13 th cross | G15: Bidi layout | H15: 126 | I15: https://maps.app.goo.gl/isNVvj3Wc2z2nD8r9 | J15: Yes | K15: Residential | L15: Concrete | M15: 5 | N15: Good | O15: North | P15: Divider (Concrete) | Q15: 0.9 | R15: 2024 | S15: Good | T15: -- | Z15: South | AA15: Divider (Concrete) | AB15: 0.9 | AC15: 2024 | AD15: Good | AE15: -- | AK15: North | AL15: FFL Gutter | AM15: 0.7 | AN15: 2024 | AO15: Good | AP15: -- | AQ15: South | AR15: 0.7 | AS15: 2014 | AT15: Good | AU15: -- | AV15: Yes | AW15: PVC | AX15: 2024 | AY15: 0.15 | AZ15: Good | BA15: Yes | BB15: Maintenance | BC15: Jalasiri existed but no water supply | BD15: LED- Pole | BE15: Good
A16: 46225.557 | C16: Soumya s s | D16: 15 | E16: 1st main | F16: 14 th cross | G16: Bidi layout | H16: 134 | I16: https://maps.app.goo.gl/PHKZsxb1V8Y7txZD7 | J16: Yes | K16: Residential | L16: Concrete | M16: 4.1 | N16: Good | O16: North | P16: Divider (Concrete) | Q16: 0.8 | R16: 2024 | S16: Good | T16: -- | Z16: South | AA16: Divider (Concrete) | AB16: 0.8 | AC16: 2024 | AD16: Good | AE16: -- | AK16: North | AL16: FFL Gutter | AM16: 0.7 | AN16: 2024 | AO16: Good | AP16: -- | AQ16: South | AR16: 0.7 | AS16: 2024 | AT16: Good | AU16: -- | AV16: Yes | AW16: PVC | AX16: 2024 | AY16: 0.15 | AZ16: Good | BA16: Yes | BB16: Good | BC16: Jalasiri existed but no water supply | BD16: LED- Pole | BE16: Good
A17: 46225.559 | C17: Soumya s s | D17: 16 | E17: 1 st main | F17: 15 th cross | G17: Bidi layout | H17: 134 | I17: https://maps.app.goo.gl/YiVV8djsuY1DHvJU9 | J17: Yes | K17: Residential | L17: Concrete | M17: 4.1 | N17: Good | O17: North | P17: Divider (Concrete) | Q17: 0.6 | R17: 2024 | S17: Good | T17: -- | Z17: South | AA17: Divider (Concrete) | AB17: 0.6 | AC17: 2024 | AD17: Good | AE17: -- | AK17: North | AL17: FFL Gutter | AM17: 0.6 | AN17: 2024 | AO17: Good | AP17: -- | AQ17: South | AR17: 0.5 | AS17: 2024 | AT17: Good | AU17: -- | AV17: Yes | AW17: PVC | AX17: 2014 | AY17: 0.15 | AZ17: Good | BA17: Yes | BB17: Good | BC17: Jalasiri existed but no water | BD17: LED- Pole | BE17: Good
A18: 46225.562 | C18: Soumya s s | D18: 17 | E18: 1 st main | F18: 16th cross | G18: Bidi layout | H18: 138 | I18: https://maps.app.goo.gl/ZQsxAzmAg1afNERX9 | J18: No | K18: Residential | L18: Concrete | M18: 2.8 | N18: Good | O18: North | P18: n/a | Q18: 0 | R18: na | S18: Required | T18: -- | Z18: South | AA18: na | AB18: 0 | AD18: Required | AK18: North | AL18: FFL Gutter | AM18: 0.9 | AN18: 2023 | AO18: Good | AP18: -- | AQ18: South | AR18: 0.9 | AS18: 2023 | AT18: Good | AU18: -- | AV18: Yes | AW18: PVC | AX18: 2024 | AY18: 0.15 | AZ18: Good | BA18: Yes | BB18: Maintenance | BC18: -- | BD18: LED- Pole | BE18: Good
A19: 46227.517 | C19: Prashantgouda | D19: 18 | E19: 1st Main | F19: 2st cross | G19: Siddrameshwara badavane | H19: 136 | I19: https://maps.app.goo.gl/UkQT9iL1ejTnDw2h7?g_st=ac | J19: Yes | K19: Residential | L19: Concrete | M19: 1.2 | N19: Good | O19: North | P19: n/a | Q19: 0 | R19: 2020 | S19: Good | T19: -- | Z19: South | AA19: n/a | AB19: 0 | AC19: na | AD19: n/a | AE19: Connected to concrete road | AK19: North | AL19: FFL Gutter | AM19: 0.6 | AN19: 2020 | AO19: Good | AP19: -- | AQ19: South | AR19: 0.6 | AS19: 2020 | AT19: Good | AU19: -- | AV19: No | AW19: n/a | AX19: na | AY19: 0 | AZ19: n/a | BA19: Yes | BB19: Maintenance | BC19: Jalasiri existed but no water supply | BD19: LED- Pole | BE19: Good
A20: 46227.521 | C20: Prashantgouda | D20: 19 | E20: 1st main | F20: 3rd cross | G20: Siddrameshwara badavane | H20: 130 | I20: https://maps.app.goo.gl/Eyop4MuNCTYp9V246?g_st=ac | J20: Yes | K20: Residential | L20: Concrete | M20: 3 | N20: Good | O20: North | P20: n/a | Q20: 0 | R20: 2020 | S20: Good | T20: Connected to concrete road | Z20: South | AA20: n/a | AB20: 0 | AC20: na | AD20: n/a | AE20: -- | AK20: North | AL20: FFL Gutter | AM20: 0.6 | AN20: 2020 | AO20: Good | AP20: -- | AQ20: South | AR20: 0 | AS20: 2020 | AT20: Good | AU20: -- | AV20: No | AW20: n/a | AX20: na | AY20: 0 | AZ20: n/a | BA20: Yes | BB20: Maintenance | BC20: -- | BD20: LED- Pole | BE20: Good
A21: 46227.528 | C21: Prashantgouda | D21: 20 | E21: 1st main | F21: 4th cross | G21: Siddrameshwara badavane | H21: 119 | I21: https://maps.app.goo.gl/fT28yezdSeraqi5F7?g_st=ac | J21: Yes | K21: Residential | L21: Concrete | M21: 2.5 | N21: Good | O21: North | P21: n/a | Q21: 0 | R21: n/a | S21: n/a | T21: -- | Z21: South | AA21: n/a | AB21: 0 | AC21: na | AD21: n/a | AE21: -- | AK21: North | AL21: FFL Gutter | AM21: 0.6 | AN21: 2020 | AO21: ?? | AP21: -- | AQ21: South | AR21: 0.6 | AS21: 2020 | AT21: Maintenance | AU21: -- | AV21: No | AW21: n/a | AX21: na | AY21: 0 | AZ21: n/a | BA21: Yes | BB21: Maintenance | BC21: Jalasiri existed but no water supply | BD21: LED- Pole | BE21: Good
A22: 46227.532 | C22: Prashantgouda | D22: 21 | E22: 1st main | F22: 5th cross | G22: Siddrameshwara badavane | H22: 100 | I22: https://maps.app.goo.gl/uwvqdukQZGHBhoeC8 | J22: Yes | K22: Residential | L22: Concrete | M22: 2.5 | N22: Good | O22: North | P22: n/a | Q22: 0 | R22: na | S22: n/a | T22: -- | Z22: South | AA22: n/a | AB22: 0 | AC22: na | AD22: n/a | AE22: -- | AK22: North | AL22: FFL Gutter | AM22: 0.6 | AN22: 2020 | AO22: Good | AP22: -- | AQ22: South | AR22: 0.6 | AS22: 2020 | AT22: Good | AU22: -- | AV22: No | AW22: n/a | AX22: na | AY22: 0 | AZ22: n/a | BA22: Yes | BB22: Maintenance | BC22: Jalasiri existed but no water supply | BD22: LED- Pole | BE22: Good
A23: 46227.534 | C23: Prashanth gouda | D23: 22 | E23: 1st main | F23: 6th cross | G23: Siddrameshwara badavane | H23: 93 | I23: https://maps.app.goo.gl/wGrr18xVuGJtkHQo9?g_st=ac | J23: Yes | K23: Residential | L23: Concrete | M23: 2.5 | N23: Good | O23: North | P23: n/a | Q23: 0 | R23: na | S23: n/a | T23: -- | Z23: South | AA23: n/a | AB23: 0 | AC23: na | AD23: n/a | AE23: -- | AK23: North | AL23: FFL Gutter | AM23: 0.6 | AN23: 2020 | AO23: Maintenance | AP23: -- | AQ23: South | AR23: 0.6 | AS23: 2020 | AT23: Maintenance | AU23: -- | AV23: No | AW23: n/a | AX23: na | AY23: 0 | AZ23: n/a | BA23: Yes | BB23: Maintenance | BC23: Jalasiri existed but no water supply | BD23: LED- Pole | BE23: Good
A24: 46227.536 | C24: Prashant gouda | D24: 23 | E24: 1st main | F24: 7th cross | G24: Siddrameshwara | H24: 60 | I24: https://maps.app.goo.gl/rcL8LVYAkqJE6gMW6 | J24: Yes | K24: Residential | L24: Concrete | M24: 3.2 | N24: Good | O24: North | P24: n/a | Q24: 0 | R24: na | S24: n/a | T24: -- | Z24: South | AA24: n/a | AB24: 0 | AC24: na | AD24: n/a | AE24: -- | AK24: North | AL24: FFL Gutter | AM24: 0.6 | AN24: 2020 | AO24: Maintenance | AP24: -- | AQ24: South | AR24: 0.6 | AS24: 2020 | AT24: Maintenance | AU24: -- | AV24: No | AW24: n/a | AX24: na | AY24: 0 | AZ24: n/a | BA24: Yes | BB24: Maintenance | BC24: -- | BD24: LED- Pole | BE24: Good
A25: 46227.539 | C25: Prashant gouda | D25: 24 | E25: 1st main | F25: 8th cross | G25: Siddrameshwara badavane | H25: 78 | I25: https://maps.app.goo.gl/34xQrweB3GAfJnLMA | J25: Yes | K25: Residential | L25: Concrete | M25: 2.5 | N25: Good | O25: North | P25: n/a | Q25: 0 | R25: na | S25: n/a | T25: -- | Z25: South | AA25: n/a | AB25: 0 | AC25: na | AD25: n/a | AE25: -- | AK25: North | AL25: FFL Gutter | AM25: 0.6 | AN25: 2020 | AO25: Maintenance | AP25: -- | AQ25: South | AR25: 0.6 | AS25: 2020 | AT25: Maintenance | AU25: -- | AV25: No | AW25: n/a | AX25: na | AY25: 0 | AZ25: n/a | BA25: Yes | BB25: Maintenance | BC25: -- | BD25: LED- Pole | BE25: Good
A26: 46227.541 | C26: Prashant gouda | D26: 25 | E26: 1st main | F26: 9th cross | G26: Siddrameshwara badavane | H26: 60 | I26: https://maps.app.goo.gl/FbwqRkSNd5Ucc5Lq6?g_st=ac | J26: Yes | K26: Residential | L26: Concrete | M26: 2.7 | N26: Good | O26: North | P26: n/a | Q26: 0 | R26: na | S26: n/a | T26: -- | Z26: South | AA26: n/a | AB26: 0 | AC26: na | AD26: n/a | AE26: -- | AK26: North | AL26: FFL Gutter | AM26: 0.6 | AN26: 2020 | AO26: Good | AP26: -- | AQ26: South | AR26: 0.6 | AS26: 2020 | AT26: Good | AU26: -- | AV26: No | AW26: n/a | AX26: na | AY26: 0 | AZ26: n/a | BA26: Yes | BB26: Maintenance | BC26: -- | BD26: LED- Pole | BE26: Good
A27: 46227.544 | C27: Prashant gouda | D27: 26 | E27: 1st main | F27: 10th cross | G27: Siddrameshwara badavane | H27: 52 | I27: https://maps.app.goo.gl/EmzyAGQpx7a9zo39A | J27: Yes | K27: Residential | L27: Concrete | M27: 2.5 | N27: Good | O27: North | P27: n/a | Q27: 0 | R27: na | S27: n/a | T27: -- | Z27: South | AA27: n/a | AB27: 0 | AC27: na | AD27: n/a | AE27: -- | AK27: North | AL27: FFL Gutter | AM27: 0.6 | AN27: 2002 | AO27: Maintenance | AP27: -- | AQ27: South | AR27: 0.6 | AS27: 2020 | AT27: Maintenance | AU27: -- | AV27: No | AW27: n/a | AX27: na | AY27: 0 | AZ27: n/a | BA27: Yes | BB27: Maintenance | BC27: -- | BD27: LED- Pole | BE27: Good
A28: 46227.546 | C28: Prashanth gouda | D28: 27 | E28: 1st main | F28: 11th cross | G28: Siddrameshwara badavane | H28: 50 | I28: https://maps.app.goo.gl/qYyV4pYMmyXpHWUS6 | J28: Yes | K28: Residential | L28: Concrete | M28: 2 | N28: Good | O28: North | P28: n/a | Q28: 0 | R28: na | S28: n/a | T28: -- | Z28: South | AA28: n/a | AB28: 0 | AC28: na | AD28: n/a | AE28: -- | AK28: North | AL28: FFL Gutter | AM28: 0.6 | AN28: 2020 | AO28: Good | AP28: -- | AQ28: South | AR28: 0.6 | AS28: 2020 | AT28: Good | AU28: -- | AV28: No | AW28: n/a | AX28: na | AY28: 0 | AZ28: n/a | BA28: Yes | BB28: Maintenance | BC28: -- | BD28: LED- Pole | BE28: Good
A29: 46228.432 | D29: 28 | E29: 1st main A | G29: Siddrameshwara badavane | H29: 225 | I29: https://maps.app.goo.gl/GCbNP1vpsCcVpKG18?g_st=ac | J29: No | K29: Residential | L29: Mud | N29: Required | O29: North | P29: Bund | Q29: ?? | R29: ?? | S29: ?? | T29: Pavement required | Z29: West | AA29: Bund | AB29: ?? | AC29: ?? | AD29: ?? | AE29: Pavement required | AK29: North | AL29: Required | AM29: 0.6 | AN29: ?? | AO29: Required | AP29: Drains required | AQ29: South | AR29: 0 | AS29: na | AT29: Required | AU29: Drains required | AV29: No | AW29: n/a | AX29: na | AY29: 0 | AZ29: n/a | BA29: No | BB29: ?? | BC29: -- | BD29: LED- Pole | BE29: Good
A30: 46228.436 | C30: Prashanth gouda | D30: 29 | E30: 1st main A1 | G30: Siddrameshwara badavane | H30: 246 | I30: https://maps.app.goo.gl/VexQPgpTcK9stuXc8 | J30: No | K30: Residential | L30: Concrete | M30: 3.7 | N30: Good | O30: North | P30: Bund | Q30: 2.2 | S30: Required | T30: -- | Z30: South | AA30: Bund | AB30: 2.2 | AC30: na | AD30: Required | AE30: -- | AK30: North | AL30: FFL Gutter | AM30: 0.6 | AN30: 2022 | AO30: Good | AP30: -- | AQ30: South | AR30: 0.6 | AS30: 2022 | AT30: Required | AU30: -- | AV30: No | AW30: n/a | AX30: na | AY30: 0 | AZ30: n/a | BA30: No | BB30: ?? | BC30: -- | BD30: LED- Pole | BE30: Good
A31: 46228.439 | C31: Prashantgouda 0 | D31: 30 | E31: 1st main A2 | G31: Siddrameshwara badavane | H31: 103 | I31: https://maps.app.goo.gl/Gyte2Ym1A7gVH1P9A?g_st=ac | J31: No | K31: Residential | L31: Mud | M31: 3.5 | N31: Good | O31: North | P31: Bund | Q31: 2.5 | S31: Required | T31: -- | Z31: South | AA31: Bund | AB31: 2.5 | AC31: na | AD31: Required | AE31: -- | AK31: North | AL31: FFL Gutter | AM31: 0.6 | AN31: 2022 | AO31: Good | AP31: -- | AQ31: South | AR31: 0.6 | AS31: 2022 | AT31: Good | AU31: -- | AV31: No | AW31: n/a | AX31: na | AY31: 0 | AZ31: n/a | BA31: No | BB31: Required | BC31: -- | BD31: LED- Pole | BE31: Good
A32: 46228.442 | C32: Prashanth gouda | D32: 31 | E32: 1st main A3 | G32: Mandaki batti | H32: 131 | I32: https://maps.app.goo.gl/EPiDB89RWVuwzdT98?g_st=ac | J32: No | K32: Residential | L32: Concrete | M32: 3.5 | N32: Good | O32: North | P32: Bund | Q32: 2.5 | S32: Required | T32: -- | Z32: South | AA32: Bund | AB32: 2.5 | AC32: na | AD32: Required | AE32: -- | AK32: North | AL32: FFL Gutter | AM32: 0.6 | AN32: 2022 | AO32: Good | AP32: -- | AQ32: South | AR32: 0.6 | AS32: 2022 | AT32: Good | AU32: -- | AV32: No | AW32: n/a | AX32: na | AY32: 0 | AZ32: n/a | BA32: No | BB32: Required | BC32: -- | BD32: LED- Pole | BE32: Good
A33: 46228.446 | C33: Prashanth gouda | D33: 32 | E33: 1st main A4 | G33: Mandaki batti | H33: 139 | I33: https://maps.app.goo.gl/roQp3nEBCazbajW98 | J33: No | K33: Residential | L33: Mud | M33: 3.5 | N33: Good | O33: East | P33: Bund | Q33: 2.5 | S33: Required | T33: -- | Z33: West | AA33: Bund | AB33: 2.5 | AC33: na | AD33: Required | AE33: -- | AK33: East | AL33: FFL Gutter | AM33: 0.6 | AN33: 2022 | AO33: Good | AP33: -- | AQ33: West | AR33: 0.6 | AS33: 2022 | AT33: Good | AU33: -- | AV33: No | AW33: n/a | AX33: na | AY33: 0 | AZ33: n/a | BA33: No | BB33: Required | BC33: -- | BD33: LED- Pole | BE33: Good
A34: 46228.449 | C34: Prashanth gouda | D34: 33 | E34: 1st main A5 | G34: Siddrameshwara badavane | H34: 104 | I34: https://maps.app.goo.gl/xpvZkofXeCZ2MJs78?g_st=ac | J34: No | K34: Residential | L34: Concrete | M34: 3.5 | N34: Good | O34: East | P34: Bund | Q34: 2.5 | S34: Required | T34: -- | Z34: West | AA34: Bund | AB34: 2.5 | AC34: na | AD34: Required | AE34: -- | AK34: East | AL34: FFL Gutter | AM34: 0.6 | AN34: 2022 | AO34: Good | AP34: -- | AQ34: West | AR34: 0.6 | AS34: 2022 | AT34: Good | AU34: -- | AV34: No | AW34: n/a | AX34: na | AY34: 0 | AZ34: n/a | BA34: No | BB34: Required | BC34: -- | BD34: LED- Pole | BE34: Good
A35: 46228.451 | C35: Prashantgouda | D35: 34 | E35: 1st main A6 | G35: Siddrameshwara badavane | H35: 103 | I35: https://maps.app.goo.gl/jN3HSy1G9U6NNS9G8 | J35: No | K35: Residential | L35: Concrete | M35: 3.5 | N35: Good | O35: East | P35: Bund | Q35: 2.5 | S35: Required | T35: -- | Z35: West | AA35: Bund | AB35: 2.5 | AC35: na | AD35: Required | AE35: -- | AK35: East | AL35: FFL Gutter | AM35: 0.6 | AN35: 2022 | AO35: Good | AP35: -- | AQ35: West | AR35: 0.6 | AS35: 2022 | AT35: Good | AU35: -- | AV35: No | AW35: n/a | AX35: na | AY35: 0 | AZ35: n/a | BA35: No | BB35: Required | BC35: -- | BD35: LED- Pole | BE35: Good
A36: 46228.454 | C36: Prashantgouda | D36: 36 | E36: 1st main A7 | G36: Siddrameshwara badavane | H36: 90 | I36: https://maps.app.goo.gl/CYcLL6F5vdt224Xw5 | J36: No | K36: Residential | L36: Concrete | M36: 3.5 | N36: Good | O36: East | P36: Bund | Q36: 2.5 | R36: na | S36: Required | T36: -- | Z36: West | AA36: Bund | AB36: 2.5 | AC36: na | AD36: Required | AE36: -- | AK36: East | AL36: FFL Gutter | AM36: 0.6 | AN36: 2022 | AO36: Good | AP36: -- | AQ36: West | AR36: 0.6 | AS36: 2022 | AT36: Good | AU36: -- | AV36: No | AW36: n/a | AX36: na | AY36: 0 | AZ36: n/a | BA36: No | BB36: Required | BC36: -- | BD36: LED- Pole | BE36: Good
A37: 46228.456 | C37: Prashanth gouda | D37: 38 | E37: 1st main A8 | G37: Siddrameshwara badavane | H37: 69 | I37: https://maps.app.goo.gl/B75DtKzRCGJ5tGgEA?g_st=ac | J37: No | K37: Residential | L37: Concrete | M37: 3.5 | N37: Good | O37: East | P37: Bund | Q37: 3.5 | R37: na | S37: ?? | T37: -- | Z37: West | AA37: Bund | AB37: 2.5 | AC37: na | AD37: ?? | AE37: -- | AK37: East | AL37: FFL Gutter | AM37: 0.6 | AN37: 2022 | AO37: Good | AP37: -- | AQ37: West | AR37: 0.6 | AS37: 2022 | AT37: Good | AU37: -- | AV37: No | AW37: n/a | AX37: na | AY37: 0 | AZ37: n/a | BA37: No | BB37: Required | BC37: -- | BD37: LED- Pole | BE37: Good
A38: 46227.453 | C38: Vishalaxi.B.T | D38: 62 | E38: 1st main | G38: Mandaki batti | H38: 232 | I38: https://maps.app.goo.gl/PS2wrF9qx4FZstJ76 | J38: No | K38: Comercial | L38: Concrete | M38: 5.3 | N38: Good | O38: East | P38: Pavers | Q38: 3 | R38: 2022 | S38: Good | T38: -- | Z38: West | AA38: Pavers | AB38: 3 | AC38: 2022 | AD38: ?? | AE38: -- | AK38: East | AL38: Elevated Gutter | AM38: 1.1 | AN38: 2022 | AO38: Good | AP38: -- | AQ38: West | AR38: 1.1 | AS38: 2022 | AT38: Good | AU38: -- | AV38: Yes | AW38: PVC | AX38: 2022 | AY38: 0.2 | AZ38: Good | BA38: No | BB38: Required | BC38: -- | BD38: LED- Pole | BE38: Good
A39: 46228.452 | C39: Vishalaxi | D39: 35 | E39: 1st main | F39: 11th cross | G39: Mandaki batti | H39: 269 | I39: https://maps.app.goo.gl/a4nSjUo1XAt5FUAw7 | J39: No | K39: Residential | L39: Concrete | M39: 5.5 | N39: Good | O39: North | P39: Bund | Q39: ?? | R39: ?? | S39: Required | T39: Pavement required | Z39: South | AA39: Bund | AB39: ?? | AC39: ?? | AD39: Required | AE39: -- | AK39: North | AL39: FFL Gutter | AM39: 1.1 | AN39: 2022 | AO39: Good | AP39: -- | AQ39: South | AR39: 1.1 | AS39: 2022 | AT39: Good | AU39: -- | AV39: Yes | AW39: PVC | AX39: 2022 | AY39: 0.15 | AZ39: Good | BA39: No | BB39: ?? | BC39: -- | BD39: LED- Pole | BE39: Good
A40: 46228.454 | D40: 37 | E40: 1st main | F40: 11 th cross A | G40: Mandaki batti | H40: 45 | I40: https://maps.app.goo.gl/oL9aC5k7Jtz1vfPQ9 | J40: No | K40: Residential | L40: Concrete | M40: 2.8 | N40: Good | O40: East | P40: n/a | Q40: 0 | R40: na | S40: n/a | T40: -- | Z40: West | AA40: n/a | AB40: 0 | AC40: na | AD40: ?? | AE40: -- | AK40: East | AL40: FFL Gutter | AM40: 0.8 | AN40: 2022 | AO40: Good | AP40: -- | AQ40: West | AR40: 0.8 | AS40: 2022 | AT40: Good | AU40: -- | AV40: Yes | AW40: PVC | AX40: 2022 | AY40: 0.15 | AZ40: Good | BA40: No | BB40: Required | BC40: -- | BD40: LED- Pole | BE40: Good
...

Sheet Data sheet
C1: Ward No: | E1: ="03" -> 03
C2: Ward Name: | E2: Siddrameshwara badavane, Mandakibatti Layout, AK Colony
C3: Total Number of Roads | F3: 93 | G3: nos
C4: Total Road Length | E4: =Form_Responses[[#TOTALS],[Dist. (m)]] -> 14071 | G4: km
E5: nos | F5: Length | G5: Area | H5: Action | I5: Std Rate min | J5: Std Rate max | K5: Estimation | L5: Notes
D6: unit | E6: # | F6: m | G6: sqm | I6: INR | K6: INR
B7: I. Road | C7: Rd.Sign | D7: Yes | E7: =COUNTIF('Form responses 1'!J2:J89,D7) -> 33 | G7: na | H7: na | I7: na | J7: na | K7: 0
D8: No | E8: =COUNTIF('Form responses 1'!J2:J89,D8) -> 55 | K8: =G8*AVERAGE(I8,J8) -> #DIV/0!
D9: Damaged | E9: =COUNTIF('Form responses 1'!J2:J89,D9) -> 0 | K9: =G9*AVERAGE(I9,J9) -> #DIV/0!
C10: Road Type | D10: Main Rd | E10: =COUNTIF('Form responses 1'!$K$2:$K$89,D10) -> 0 | G10: {=SUM(IF('Form responses 1'!$K$2:$K$89 = D10,'Form responses 1'!$H$2:$H$89*'Form responses 1'!$M$2:$M$89, ""))} -> 0 | H10: na | I10: na | J10: na | K10: 0
D11: Comercial | E11: =COUNTIF('Form responses 1'!$K$2:$K$89,D11) -> 18 | G11: {=SUM(IF('Form responses 1'!$K$2:$K$89 = D11,'Form responses 1'!$H$2:$H$89*'Form responses 1'!$M$2:$M$89, ""))} -> 29394.4 | H11: na | I11: na | J11: na | K11: 0
D12: Residential | E12: =COUNTIF('Form responses 1'!$K$2:$K$89,D12) -> 70 | G12: {=SUM(IF('Form responses 1'!$K$2:$K$89 = D12,'Form responses 1'!$H$2:$H$89*'Form responses 1'!$M$2:$M$89, ""))} -> 31110.5 | H12: na | I12: na | J12: na | K12: 0
D13: Conservency | E13: =COUNTIF('Form responses 1'!$K$2:$K$89,D13) -> 0 | G13: {=SUM(IF('Form responses 1'!$K$2:$K$89 = D13,'Form responses 1'!$H$2:$H$89*'Form responses 1'!$M$2:$M$89, ""))} -> 0 | H13: na | I13: na | J13: na | K13: 0
C14: Road Type | D14: Concrete | E14: =COUNTIF('Form responses 1'!$L$2:$L$89,D14) -> 83 | G14: {=SUM(IF('Form responses 1'!$L$2:$L$89 = D14,'Form responses 1'!$H$2:$H$89*'Form responses 1'!$M$2:$M$89, ""))} -> 58564.6 | K14: =G14*AVERAGE(I14,J14) -> #DIV/0!
D15: Gravell | E15: =COUNTIF('Form responses 1'!$L$2:$L$89,D15) -> 1 | G15: {=SUM(IF('Form responses 1'!$L$2:$L$89 = D15,'Form responses 1'!$H$2:$H$89*'Form responses 1'!$M$2:$M$89, ""))} -> 939.6 | H15: Convert to concrete | I15: 2000 | K15: =G15*AVERAGE(I15,J15) -> 1879200
D16: Mud | E16: =COUNTIF('Form responses 1'!$L$2:$L$89,D16) -> 4 | G16: {=SUM(IF('Form responses 1'!$L$2:$L$89 = D16,'Form responses 1'!$H$2:$H$89*'Form responses 1'!$M$2:$M$89, ""))} -> 1000.7 | H16: Convert to concrete | I16: 3500 | K16: =G16*AVERAGE(I16,J16) -> 3502450
D17: Tar | E17: =COUNTIF('Form responses 1'!$L$2:$L$89,D17) -> 0 | G17: {=SUM(IF('Form responses 1'!$L$2:$L$89 = D17,'Form responses 1'!$H$2:$H$89*'Form responses 1'!$M$2:$M$89, ""))} -> 0 | K17: =G17*AVERAGE(I17,J17) -> #DIV/0!
D18: White Topping | E18: =COUNTIF('Form responses 1'!$L$2:$L$89,D18) -> 0 | G18: {=SUM(IF('Form responses 1'!$L$2:$L$89 = D18,'Form responses 1'!$H$2:$H$89*'Form responses 1'!$M$2:$M$89, ""))} -> 0 | K18: =G18*AVERAGE(I18,J18) -> #DIV/0!
B19: II. Attachment (N,S,E,W) | C19: Type (N/S) + (E/W) | D19: Pavers | E19: =COUNTIF('Form responses 1'!$P$2:$P$89,D19)+COUNTIF('Form responses 1'!$AA$2:$AA$89,D19) -> 39 | G19: =SUMPRODUCT(('Form responses 1'!$P$2:$P$89=D19)*'Form responses 1'!$H$2:$H$89*N('Form responses 1'!$Q$2:$Q$89))+SUMPRODUCT(('Form responses 1'!$AA$2:$AA$89=D19)*'Form responses 1'!$H$2:$H$89*N('Form responses 1'!$AB$2:$AB$89)) -> 12210.4 | I19: 2100 | K19: =G19*AVERAGE(I19,J19) -> 25641840
D20: Pavers (Elevated) | E20: =COUNTIF('Form responses 1'!$P$2:$P$89,D20)+COUNTIF('Form responses 1'!$AA$2:$AA$89,D20) -> 2 | G20: =SUMPRODUCT(('Form responses 1'!$P$2:$P$89=D20)*'Form responses 1'!$H$2:$H$89*N('Form responses 1'!$Q$2:$Q$89))+SUMPRODUCT(('Form responses 1'!$AA$2:$AA$89=D20)*'Form responses 1'!$H$2:$H$89*N('Form responses 1'!$AB$2:$AB$89)) -> 142.8 | I20: 1800 | J20: 1500 | K20: =G20*AVERAGE(I20,J20) -> 235620
D21: Pavers Ramp (Elevated) | E21: =COUNTIF('Form responses 1'!$P$2:$P$89,D21)+COUNTIF('Form responses 1'!$AA$2:$AA$89,D21) -> 0 | G21: =SUMPRODUCT(('Form responses 1'!$P$2:$P$89=D21)*'Form responses 1'!$H$2:$H$89*N('Form responses 1'!$Q$2:$Q$89))+SUMPRODUCT(('Form responses 1'!$AA$2:$AA$89=D21)*'Form responses 1'!$H$2:$H$89*N('Form responses 1'!$AB$2:$AB$89)) -> 0 | I21: 1800 | K21: =G21*AVERAGE(I21,J21) -> 0
D22: Divider (Concrete) | E22: =COUNTIF('Form responses 1'!$P$2:$P$89,D22)+COUNTIF('Form responses 1'!$AA$2:$AA$89,D22) -> 19 | G22: =SUMPRODUCT(('Form responses 1'!$P$2:$P$89=D22)*'Form responses 1'!$H$2:$H$89*N('Form responses 1'!$Q$2:$Q$89))+SUMPRODUCT(('Form responses 1'!$AA$2:$AA$89=D22)*'Form responses 1'!$H$2:$H$89*N('Form responses 1'!$AB$2:$AB$89)) -> 4558.6 | K22: =G22*AVERAGE(I22,J22) -> #DIV/0!
D23: Divider (Planter) | E23: =COUNTIF('Form responses 1'!$P$2:$P$89,D23)+COUNTIF('Form responses 1'!$AA$2:$AA$89,D23) -> 0 | G23: =SUMPRODUCT(('Form responses 1'!$P$2:$P$89=D23)*'Form responses 1'!$H$2:$H$89*N('Form responses 1'!$Q$2:$Q$89))+SUMPRODUCT(('Form responses 1'!$AA$2:$AA$89=D23)*'Form responses 1'!$H$2:$H$89*N('Form responses 1'!$AB$2:$AB$89)) -> 0 | K23: =G23*AVERAGE(I23,J23) -> #DIV/0!
D24: Curb (Planterbox) | E24: =COUNTIF('Form responses 1'!$P$2:$P$89,D24)+COUNTIF('Form responses 1'!$AA$2:$AA$89,D24) -> 0 | G24: =SUMPRODUCT(('Form responses 1'!$P$2:$P$89=D24)*'Form responses 1'!$H$2:$H$89*N('Form responses 1'!$Q$2:$Q$89))+SUMPRODUCT(('Form responses 1'!$AA$2:$AA$89=D24)*'Form responses 1'!$H$2:$H$89*N('Form responses 1'!$AB$2:$AB$89)) -> 0 | K24: =G24*AVERAGE(I24,J24) -> #DIV/0!
D25: Exposed Soil | E25: =COUNTIF('Form responses 1'!$P$2:$P$89,D25)+COUNTIF('Form responses 1'!$AA$2:$AA$89,D25) -> 0 | G25: =SUMPRODUCT(('Form responses 1'!$P$2:$P$89=D25)*'Form responses 1'!$H$2:$H$89*N('Form responses 1'!$Q$2:$Q$89))+SUMPRODUCT(('Form responses 1'!$AA$2:$AA$89=D25)*'Form responses 1'!$H$2:$H$89*N('Form responses 1'!$AB$2:$AB$89)) -> 0 | H25: PER CUM | I25: 452 | K25: =G25*AVERAGE(I25,J25) -> 0
D26: Bund | E26: =COUNTIF('Form responses 1'!$P$2:$P$89,D26)+COUNTIF('Form responses 1'!$AA$2:$AA$89,D26) -> 50 | G26: =SUMPRODUCT(('Form responses 1'!$P$2:$P$89=D26)*'Form responses 1'!$H$2:$H$89*N('Form responses 1'!$Q$2:$Q$89))+SUMPRODUCT(('Form responses 1'!$AA$2:$AA$89=D26)*'Form responses 1'!$H$2:$H$89*N('Form responses 1'!$AB$2:$AB$89)) -> 7401.15 | K26: =G26*AVERAGE(I26,J26) -> #DIV/0!
D27: Bund | E27: =COUNTIF('Form responses 1'!$P$2:$P$89,D27)+COUNTIF('Form responses 1'!$AA$2:$AA$89,D27) -> 50 | G27: =SUMPRODUCT(('Form responses 1'!$P$2:$P$89=D27)*'Form responses 1'!$H$2:$H$89*N('Form responses 1'!$Q$2:$Q$89))+SUMPRODUCT(('Form responses 1'!$AA$2:$AA$89=D27)*'Form responses 1'!$H$2:$H$89*N('Form responses 1'!$AB$2:$AB$89)) -> 7401.15 | K27: =G27*AVERAGE(I27,J27) -> #DIV/0!
D28: n/a | E28: =COUNTIF('Form responses 1'!$P$2:$P$89,D28)+COUNTIF('Form responses 1'!$AA$2:$AA$89,D28) -> 64 | G28: =SUMPRODUCT(('Form responses 1'!$P$2:$P$89=D28)*'Form responses 1'!$H$2:$H$89*N('Form responses 1'!$Q$2:$Q$89))+SUMPRODUCT(('Form responses 1'!$AA$2:$AA$89=D28)*'Form responses 1'!$H$2:$H$89*N('Form responses 1'!$AB$2:$AB$89)) -> 0 | K28: =G28*AVERAGE(I28,J28) -> #DIV/0!
C29: Condition | D29: Good | E29: =COUNTIF('Form responses 1'!$S$2:$S$89,D29)+COUNTIF('Form responses 1'!$AD$2:$AD$89,D29) -> 62 | G29: =SUMPRODUCT(('Form responses 1'!$S$2:$S$89=D29)*'Form responses 1'!$H$2:$H$89*N('Form responses 1'!$Q$2:$Q$89))+SUMPRODUCT(('Form responses 1'!$AD$2:$AD$89=D29)*'Form responses 1'!$H$2:$H$89*N('Form responses 1'!$AB$2:$AB$89)) -> 16050.9 | K29: =G29*AVERAGE(I29,J29) -> #DIV/0!
D30: Required | E30: =COUNTIF('Form responses 1'!$S$2:$S$89,D30)+COUNTIF('Form responses 1'!$AD$2:$AD$89,D30) -> 48 | G30: =SUMPRODUCT(('Form responses 1'!$S$2:$S$89=D30)*'Form responses 1'!$H$2:$H$89*N('Form responses 1'!$Q$2:$Q$89))+SUMPRODUCT(('Form responses 1'!$AD$2:$AD$89=D30)*'Form responses 1'!$H$2:$H$89*N('Form responses 1'!$AB$2:$AB$89)) -> 7048.55 | K30: =G30*AVERAGE(I30,J30) -> #DIV/0!
D31: Additional Required | E31: =COUNTIF('Form responses 1'!$S$2:$S$89,D31)+COUNTIF('Form responses 1'!$AD$2:$AD$89,D31) -> 0 | G31: =SUMPRODUCT(('Form responses 1'!$S$2:$S$89=D31)*'Form responses 1'!$H$2:$H$89*N('Form responses 1'!$Q$2:$Q$89))+SUMPRODUCT(('Form responses 1'!$AD$2:$AD$89=D31)*'Form responses 1'!$H$2:$H$89*N('Form responses 1'!$AB$2:$AB$89)) -> 0 | K31: =G31*AVERAGE(I31,J31) -> #DIV/0!
D32: Outdated | E32: =COUNTIF('Form responses 1'!$S$2:$S$89,D32)+COUNTIF('Form responses 1'!$AD$2:$AD$89,D32) -> 0 | G32: =SUMPRODUCT(('Form responses 1'!$S$2:$S$89=D32)*'Form responses 1'!$H$2:$H$89*N('Form responses 1'!$Q$2:$Q$89))+SUMPRODUCT(('Form responses 1'!$AD$2:$AD$89=D32)*'Form responses 1'!$H$2:$H$89*N('Form responses 1'!$AB$2:$AB$89)) -> 0 | K32: =G32*AVERAGE(I32,J32) -> #DIV/0!
D33: Maintenance | E33: =COUNTIF('Form responses 1'!$S$2:$S$89,D33)+COUNTIF('Form responses 1'!$AD$2:$AD$89,D33) -> 0 | G33: =SUMPRODUCT(('Form responses 1'!$S$2:$S$89=D33)*'Form responses 1'!$H$2:$H$89*N('Form responses 1'!$Q$2:$Q$89))+SUMPRODUCT(('Form responses 1'!$AD$2:$AD$89=D33)*'Form responses 1'!$H$2:$H$89*N('Form responses 1'!$AB$2:$AB$89)) -> 0 | K33: =G33*AVERAGE(I33,J33) -> #DIV/0!
D34: n/a | E34: =COUNTIF('Form responses 1'!$S$2:$S$89,D34)+COUNTIF('Form responses 1'!$AD$2:$AD$89,D34) -> 52 | G34: =SUMPRODUCT(('Form responses 1'!$S$2:$S$89=D34)*'Form responses 1'!$H$2:$H$89*N('Form responses 1'!$Q$2:$Q$89))+SUMPRODUCT(('Form responses 1'!$AD$2:$AD$89=D34)*'Form responses 1'!$H$2:$H$89*N('Form responses 1'!$AB$2:$AB$89)) -> 0 | K34: =G34*AVERAGE(I34,J34) -> #DIV/0!
B35: III. SWG (N,S,E,W) | D35: FFL Gutter | E35: =COUNTIF('Form responses 1'!$AL$2:$AL$89,D35) -> 73 | G35: =SUMPRODUCT(('Form responses 1'!$AL$2:$AL$89=D35)*'Form responses 1'!$H$2:$H$89*N('Form responses 1'!$AM$2:$AM$89))+SUMPRODUCT(('Form responses 1'!$AL$2:$AL$89=D35)*'Form responses 1'!$H$2:$H$89*N('Form responses 1'!$AR$2:$AR$89)) -> 12615.5 | H35: 0.6 | I35: 6000 | K35: =G35*AVERAGE(I35,J35) -> 75693000
D36: Elevated Gutter | E36: =COUNTIF('Form responses 1'!$AL$2:$AL$89,D36) -> 12 | G36: =SUMPRODUCT(('Form responses 1'!$AL$2:$AL$89=D36)*'Form responses 1'!$H$2:$H$89*N('Form responses 1'!$AM$2:$AM$89))+SUMPRODUCT(('Form responses 1'!$AL$2:$AL$89=D36)*'Form responses 1'!$H$2:$H$89*N('Form responses 1'!$AR$2:$AR$89)) -> 5912.9 | H36: 0.6 | I36: 6000 | K36: =G36*AVERAGE(I36,J36) -> 35477400
D37: No Gutter req | E37: =COUNTIF('Form responses 1'!$AL$2:$AL$89,D37) -> 0 | G37: =SUMPRODUCT(('Form responses 1'!$AL$2:$AL$89=D37)*'Form responses 1'!$H$2:$H$89*N('Form responses 1'!$AM$2:$AM$89))+SUMPRODUCT(('Form responses 1'!$AL$2:$AL$89=D37)*'Form responses 1'!$H$2:$H$89*N('Form responses 1'!$AR$2:$AR$89)) -> 0 | K37: =G37*AVERAGE(I37,J37) -> #DIV/0!
D38: Required | E38: =COUNTIF('Form responses 1'!$AL$2:$AL$89,D38) -> 2 | G38: =SUMPRODUCT(('Form responses 1'!$AL$2:$AL$89=D38)*'Form responses 1'!$H$2:$H$89*N('Form responses 1'!$AM$2:$AM$89))+SUMPRODUCT(('Form responses 1'!$AL$2:$AL$89=D38)*'Form responses 1'!$H$2:$H$89*N('Form responses 1'!$AR$2:$AR$89)) -> 135 | H38: 0.6 | I38: 6000 | K38: =G38*AVERAGE(I38,J38) -> 810000
C39: Condition | D39: Good | E39: =COUNTIF('Form responses 1'!$AO$2:$AO$89,D39)+COUNTIF('Form responses 1'!$AT$2:$AT$89,D39) -> 155 | G39: =SUMPRODUCT(('Form responses 1'!$AO$2:$AO$89=D39)*'Form responses 1'!$H$2:$H$89*N('Form responses 1'!$AM$2:$AM$89))+SUMPRODUCT(('Form responses 1'!$AT$2:$AT$89=D39)*'Form responses 1'!$H$2:$H$89*N('Form responses 1'!$AR$2:$AR$89)) -> 17769.8 | K39: =G39*AVERAGE(I39,J39) -> #DIV/0!
D40: Required | E40: =COUNTIF('Form responses 1'!$AO$2:$AO$89,D40)+COUNTIF('Form responses 1'!$AT$2:$AT$89,D40) -> 7 | G40: =SUMPRODUCT(('Form responses 1'!$AO$2:$AO$89=D40)*'Form responses 1'!$H$2:$H$89*N('Form responses 1'!$AM$2:$AM$89))+SUMPRODUCT(('Form responses 1'!$AT$2:$AT$89=D40)*'Form responses 1'!$H$2:$H$89*N('Form responses 1'!$AR$2:$AR$89)) -> 282.6 | K40: =G40*AVERAGE(I40,J40) -> #DIV/0!
...

Sheet Sheet5
